Workbook

Sheet Balance Sheet
A1: GUPTA AGENCY
A2: (Proprietor: Subhash Chander Gupta)
A3: H-129, Mohammadpur Village, New Delhi – 110066 | PAN: ABZPG3547J | GSTIN: 07ABZPG3547J1Z3
A4: Balance Sheet as at 31st March 2026
D5: (Amount in ₹)
A6: Particulars | B6: Note No. | C6: As at 31.03.2026 | D6: As at 31.03.2025
A7: I. SOURCES OF FUNDS (EQUITY AND LIABILITIES) | F7: Check (L – A)
A8: 1. Proprietor's Funds | F8: =C18-C31 -> 0 | G8: =D18-D31 -> 0
A9: Proprietor's Capital Account | B9: 1 | C9: =Notes!B13 -> 2590190 | D9: =Notes!C13 -> 2659951
A10: 2. Non-Current Liabilities
A11: Long-term Borrowings – Secured | B11: 2 | C11: =Notes!B27 -> 48832971 | D11: =Notes!C27 -> 46835142
A12: Long-term Borrowings – Unsecured | B12: 3 | C12: =Notes!B44 -> 11598279 | D12: =Notes!C44 -> 2847971
A13: 3. Current Liabilities
A14: Short-term Borrowings | B14: 4 | C14: =Notes!B50 -> 19346532 | D14: =Notes!C50 -> 19533675
A15: Trade Payables | B15: 5 | C15: =Notes!B56 -> 155101 | D15: =Notes!C56 -> 174780
A16: Other Current Liabilities | B16: 6 | C16: =Notes!B69 -> 3934874 | D16: =Notes!C69 -> 3321223
A17: Short-term Provisions | B17: 7 | C17: =Notes!B76 -> 100000 | D17: =Notes!C76 -> 166092
A18: TOTAL | C18: =C9+C11+C12+C14+C15+C16+C17 -> 86557947 | D18: =D9+D11+D12+D14+D15+D16+D17 -> 75538834
A20: II. APPLICATION OF FUNDS (ASSETS)
A21: 1. Non-Current Assets
A22: Property, Plant & Equipment | B22: 8 | C22: =Notes!B86 -> 4842280 | D22: =Notes!C86 -> 4619487
A23: Capital Work-in-Progress | B23: 10 | C23: =Notes!B98 -> 49766550 | D23: =Notes!C98 -> 43674985
A24: Non-current Investments | B24: 9 | C24: =Notes!B92 -> 740211 | D24: =Notes!C92 -> 621384
A25: 2. Current Assets
A26: Inventories | B26: 11 | C26: =Notes!B109 -> 15114117 | D26: =Notes!C109 -> 15989062
A27: Trade Receivables | B27: 12 | C27: =Notes!B116 -> 8718676 | D27: =Notes!C116 -> 1984859
A28: Cash and Cash Equivalents | B28: 13 | C28: =Notes!B125 -> 2116027 | D28: =Notes!C125 -> 2584144
A29: Short-term Loans and Advances | B29: 14 | C29: =Notes!B136 -> 870302 | D29: =Notes!C136 -> 2822046
A30: Other Current Assets | B30: 15 | C30: =Notes!B143 -> 4389784 | D30: =Notes!C143 -> 3242867
A31: TOTAL | C31: =C22+C23+C24+C26+C27+C28+C29+C30 -> 86557947 | D31: =D22+D23+D24+D26+D27+D28+D29+D30 -> 75538834
A33: Significant Accounting Policies and Notes to Accounts – Note 26. The notes and schedules form an integral part of the financial statements.
A36: As per our report of even date attached | C36: For and on behalf of
A37: For G R B & Co. | C37: GUPTA AGENCY
A38: Chartered Accountants
A39: FRN: 040755N
A45: CA Roopali Garg
A46: Partner | C46: Subhash Chander Gupta
A47: M. No. 570376 | C47: Proprietor
A48: UDIN: ____________________
A49: Place: Delhi
...

Sheet Profit & Loss
A1: GUPTA AGENCY
A2: (Proprietor: Subhash Chander Gupta)
A3: H-129, Mohammadpur Village, New Delhi – 110066 | PAN: ABZPG3547J | GSTIN: 07ABZPG3547J1Z3
A4: Statement of Profit & Loss for the year ended 31st March 2026
D5: (Amount in ₹)
A6: Particulars | B6: Note No. | C6: Year ended 31.03.2026 | D6: Year ended 31.03.2025
A7: I. Revenue from Operations | B7: 16 | C7: =Notes!B150 -> 1.351257e+08 | D7: =Notes!C150 -> 1.6220183e+08
A8: II. Other Income | B8: 17 | C8: =Notes!B164 -> 4326221 | D8: =Notes!C164 -> 5179517.4
A9: III. Total Income (I + II) | C9: =C7+C8 -> 1.3945192e+08 | D9: =D7+D8 -> 1.6738135e+08
A11: IV. Expenses
A12: Purchases of Stock-in-Trade | B12: 18 | C12: =Notes!B170 -> 128361664 | D12: =Notes!C170 -> 162799375
A13: Changes in Inventories of Stock-in-Trade | B13: 19 | C13: =Notes!B177 -> 874945.52 | D13: =Notes!C177 -> -3971236.9
A14: Direct Expenses | B14: 20 | C14: =Notes!B183 -> 142712 | D14: =Notes!C183 -> 204399.24
A15: Employee Benefit Expenses | B15: 21 | C15: =Notes!B190 -> 2735863 | D15: =Notes!C190 -> 2540800
A16: Finance Costs | B16: 22 | C16: =Notes!B199 -> 2910532.2 | D16: =Notes!C199 -> 1836152.2
A17: Depreciation | B17: 23 | C17: =Notes!B205 -> 778873 | D17: =Notes!C205 -> 665014
A18: Other Expenses | B18: 24 | C18: =Notes!B220 -> 2019258.3 | D18: =Notes!C220 -> 1769493.8
A19: Total Expenses (IV) | C19: =SUM(C12:C18) -> 1.3782385e+08 | D19: =SUM(D12:D18) -> 1.65844e+08
A21: V. Profit before Tax (III – IV) | C21: =C9-C19 -> 1628076.6 | D21: =D9-D19 -> 1537354
A22: VI. Tax Expense – Current Tax | B22: 25 | C22: =Notes!B226 -> 100000 | D22: =Notes!C226 -> 166092
A23: VII. Net Profit for the year transferred to Capital Account | C23: =C21-C22 -> 1528076.6 | D23: =D21-D22 -> 1371262
A25: Significant Accounting Policies and Notes to Accounts – Note 26. The notes and schedules form an integral part of the financial statements.
A28: As per our report of even date attached | C28: For and on behalf of
A29: For G R B & Co. | C29: GUPTA AGENCY
A30: Chartered Accountants
A31: FRN: 040755N
A37: CA Roopali Garg
A38: Partner | C38: Subhash Chander Gupta
A39: M. No. 570376 | C39: Proprietor
A40: UDIN: ____________________
A41: Place: Delhi
A42: Date: 25/09/2026

Sheet Notes
A1: GUPTA AGENCY
A2: (Proprietor: Subhash Chander Gupta)
A3: H-129, Mohammadpur Village, New Delhi – 110066 | PAN: ABZPG3547J | GSTIN: 07ABZPG3547J1Z3
A4: Notes forming part of the Financial Statements for the year ended 31st March 2026
C5: (Amount in ₹)
A6: Note 1: Proprietor's Capital Account – Subhash Chander Gupta
A7: Particulars | B7: 31.03.2026 | C7: 31.03.2025
A8: Opening Balance | B8: 2659951 | C8: 1287164.9
A9: Add: Capital Introduced | B9: 0 | C9: 4580904
A10: Add: Net Profit for the year (as per Profit & Loss Statement) | B10: ='Profit & Loss'!C23 -> 1528076.6 | C10: ='Profit & Loss'!D23 -> 1371262
A11: Less: Drawings | B11: 1597838 | C11: 4579380.3
A12: Add: Round Off | B12: 0.36 | C12: 0.33
A13: Closing Balance | B13: =B8+B9+B10-B11+B12 -> 2590190 | C13: =C8+C9+C10-C11+C12 -> 2659951
A14: Capital balances are rounded off to the nearest rupee.
A17: Note 2: Long-term Borrowings – Secured Loans (Refer Schedule B)
A18: Particulars | B18: As at 31.03.2026 | C18: As at 31.03.2025
A19: Axis Bank Ltd. – Loan Against Property (A/c 8038) | B19: 11437844 | C19: 0
A20: Cholamandalam Investment & Finance Co. Ltd. (closed – taken over by Axis) | B20: 0 | C20: 11095269
A21: HDB Financial Services – CV Loan A/c 61294244 | B21: 651480 | C21: 769835
A22: HDB Financial Services – CV Loan A/c 61618043 | B22: 651480 | C22: 769835
A23: HDB Financial Services – CV Loan A/c 61620994 | B23: 651480 | C23: 769835
A24: ICICI Bank – Car Loan A/c LADEL00045571235 | B24: 37765 | C24: 473938
A25: Muthoot Finance Ltd. – Gold Loan | B25: 6897966 | C25: 3522857
A26: State Bank of India (RACPC) – Home Loan | B26: 28504956 | C26: 29433573
A27: Total | B27: =SUM(B19,B20,B21,B22,B23,B24,B25,B26) -> 48832971 | C27: =SUM(C19,C20,C21,C22,C23,C24,C25,C26) -> 46835142
A30: Note 3: Long-term Borrowings – Unsecured Loans (Refer Schedule B)
A31: Particulars | B31: As at 31.03.2026 | C31: As at 31.03.2025
A32: From NBFCs:
A33: Bajaj Finance Ltd. | B33: 3875890 | C33: 0
A34: Poonawalla Fincorp Ltd. | B34: 2708364 | C34: 0
A35: SMFG India Credit Co. Ltd. | B35: 2700074 | C35: 0
A36: From Friends & Relatives:
A37: Advance from Bhola | B37: 710059 | C37: 454538
A38: Advance from Sanjay Gupta | B38: 1403892 | C38: 474993
A39: Anupam Gupta | B39: 200000 | C39: 200000
A40: Advance from Anita Gupta | B40: 0 | C40: 246000
A41: Advance from Rani Gupta | B41: 0 | C41: 256000
A42: Advance from Ravi Kant | B42: 0 | C42: 836440
A43: Advance from Suman | B43: 0 | C43: 380000
A44: Total | B44: =SUM(B33,B34,B35,B37,B38,B39,B40,B41,B42,B43) -> 11598279 | C44: =SUM(C33,C34,C35,C37,C38,C39,C40,C41,C42,C43) -> 2847971
...

Sheet Sch A - Depreciation
A1: GUPTA AGENCY
A2: (Proprietor: Subhash Chander Gupta)
A3: H-129, Mohammadpur Village, New Delhi – 110066 | PAN: ABZPG3547J | GSTIN: 07ABZPG3547J1Z3
A4: Schedule A – Depreciation as per Section 32 of the Income-tax Act, 1961 (FY 2025-26, AY 2026-27)
I5: (Amount in ₹)
A6: Particulars | B6: WDV as on 01.04.2025 | C6: Additions ≥ 180 days | D6: Additions < 180 days | E6: Deletions (Sale proceeds) | F6: Total as on 31.03.2026 | G6: Rate | H6: Depreciation for the year | I6: WDV as on 31.03.2026
A7: Plant & Machinery
A8: Activa 125 | B8: 19294.958 | C8: 0 | D8: 0 | E8: 0 | F8: =B8+C8+D8-E8 -> 19294.958 | G8: 0.15 | H8: 2894 | I8: =IF(E8>0,0,F8-H8) -> 16400.958
A9: CYCLE | B9: 3051.6615 | C9: 0 | D9: 0 | E9: 0 | F9: =B9+C9+D9-E9 -> 3051.6615 | G9: 0.15 | H9: 458 | I9: =IF(E9>0,0,F9-H9) -> 2593.6615
A10: SAC LG LSAQ18GNZA | B10: 14212.468 | C10: 0 | D10: 0 | E10: 0 | F10: =B10+C10+D10-E10 -> 14212.468 | G10: 0.15 | H10: 2132 | I10: =IF(E10>0,0,F10-H10) -> 12080.468
A11: Tata 709 LPT Truck | B11: 204520.69 | C11: 0 | D11: 0 | E11: 183195 | F11: =B11+C11+D11-E11 -> 21325.693 | G11: 0.15 | H11: 15339 | I11: =IF(E11>0,0,F11-H11) -> 0
A12: TATA ACE | B12: 526811.36 | C12: 0 | D12: 0 | E12: 0 | F12: =B12+C12+D12-E12 -> 526811.36 | G12: 0.15 | H12: 79022 | I12: =IF(E12>0,0,F12-H12) -> 447789.36
A13: MOTER CYCLE | B13: 2264.3065 | C13: 0 | D13: 0 | E13: 0 | F13: =B13+C13+D13-E13 -> 2264.3065 | G13: 0.15 | H13: 340 | I13: =IF(E13>0,0,F13-H13) -> 1924.3065
A14: MARUTI ALTO | B14: 8818.937 | C14: 0 | D14: 0 | E14: 0 | F14: =B14+C14+D14-E14 -> 8818.937 | G14: 0.15 | H14: 1323 | I14: =IF(E14>0,0,F14-H14) -> 7495.937
A15: MARUTI EECO | B15: 54716.073 | C15: 0 | D15: 0 | E15: 0 | F15: =B15+C15+D15-E15 -> 54716.073 | G15: 0.15 | H15: 8207 | I15: =IF(E15>0,0,F15-H15) -> 46509.073
A16: MARUTI EECO II | B16: 73228.766 | C16: 0 | D16: 0 | E16: 0 | F16: =B16+C16+D16-E16 -> 73228.766 | G16: 0.15 | H16: 10984 | I16: =IF(E16>0,0,F16-H16) -> 62244.766
A17: MARUTI SWIFT VXI | B17: 64083.226 | C17: 0 | D17: 0 | E17: 0 | F17: =B17+C17+D17-E17 -> 64083.226 | G17: 0.15 | H17: 9612 | I17: =IF(E17>0,0,F17-H17) -> 54471.226
A18: FIRE EQUIPMENT | B18: 218.8665 | C18: 0 | D18: 0 | E18: 0 | F18: =B18+C18+D18-E18 -> 218.8665 | G18: 0.15 | H18: 33 | I18: =IF(E18>0,0,F18-H18) -> 185.8665
A19: Activa 6G | B19: 35195.95 | C19: 0 | D19: 0 | E19: 0 | F19: =B19+C19+D19-E19 -> 35195.95 | G19: 0.15 | H19: 5279 | I19: =IF(E19>0,0,F19-H19) -> 29916.95
... A29: New Scorpio Diesal | B29: 1310134.8 | C29: 0 | D29: 0 | E29: 0 | F29: =B29+C29+D29-E29 -> 1310134.8 | G29: 0.15 | H29: 196520 | I29: =IF(E29>0,0,F29-H29) -> 1113614.8
A30: Furniture & Fixtures
A31: FURNITURE & FIXTURES | B31: 55515.6 | C31: 0 | D31: 0 | E31: 0 | F31: =B31+C31+D31-E31 -> 55515.6 | G31: 0.1 | H31: 5552 | I31: =IF(E31>0,0,F31-H31) -> 49963.6
A32: Electronics
A33: Blutooth Printer | B33: 4862.374 | C33: 0 | D33: 0 | E33: 0 | F33: =B33+C33+D33-E33 -> 4862.374 | G33: 0.15 | H33: 729 | I33: =IF(E33>0,0,F33-H33) -> 4133.374
A34: COMPUTER | B34: 854.124 | C34: 0 | D34: 0 | E34: 0 | F34: =B34+C34+D34-E34 -> 854.124 | G34: 0.4 | H34: 342 | I34: =IF(E34>0,0,F34-H34) -> 512.124
A35: INVERTER | B35: 1096.6955 | C35: 0 | D35: 0 | E35: 0 | F35: =B35+C35+D35-E35 -> 1096.6955 | G35: 0.15 | H35: 165 | I35: =IF(E35>0,0,F35-H35) -> 931.6955
A36: LG 139CM SMART TV | B36: 25145.474 | C36: 0 | D36: 0 | E36: 0 | F36: =B36+C36+D36-E36 -> 25145.474 | G36: 0.15 | H36: 3772 | I36: =IF(E36>0,0,F36-H36) -> 21373.474
A37: PRINTER | B37: 1902.1895 | C37: 0 | D37: 0 | E37: 0 | F37: =B37+C37+D37-E37 -> 1902.1895 | G37: 0.15 | H37: 285 | I37: =IF(E37>0,0,F37-H37) -> 1617.1895
A38: REFRIGERATOR | B38: 385.5345 | C38: 0 | D38: 0 | E38: 0 | F38: =B38+C38+D38-E38 -> 385.5345 | G38: 0.15 | H38: 58 | I38: =IF(E38>0,0,F38-H38) -> 327.5345
A39: UPS | B39: 619.106 | C39: 0 | D39: 0 | E39: 0 | F39: =B39+C39+D39-E39 -> 619.106 | G39: 0.15 | H39: 93 | I39: =IF(E39>0,0,F39-H39) -> 526.106
A40: MOBILE | B40: 35818.889 | C40: 0 | D40: 0 | E40: 0 | F40: =B40+C40+D40-E40 -> 35818.889 | G40: 0.15 | H40: 5373 | I40: =IF(E40>0,0,F40-H40) -> 30445.889
A41: HomeTheater | B41: 34303.394 | C41: 0 | D41: 0 | E41: 0 | F41: =B41+C41+D41-E41 -> 34303.394 | G41: 0.15 | H41: 5146 | I41: =IF(E41>0,0,F41-H41) -> 29157.394
A42: HomeTheater | B42: 31066.661 | C42: 0 | D42: 0 | E42: 0 | F42: =B42+C42+D42-E42 -> 31066.661 | G42: 0.15 | H42: 4660 | I42: =IF(E42>0,0,F42-H42) -> 26406.661
A43: Iphone | B43: 111723.88 | C43: 0 | D43: 0 | E43: 0 | F43: =B43+C43+D43-E43 -> 111723.88 | G43: 0.15 | H43: 16759 | I43: =IF(E43>0,0,F43-H43) -> 94964.88
A44: Samsung | B44: 90474.68 | C44: 0 | D44: 0 | E44: 0 | F44: =B44+C44+D44-E44 -> 90474.68 | G44: 0.15 | H44: 13571 | I44: =IF(E44>0,0,F44-H44) -> 76903.68
... A49: SAMSUNG 83 S90F T.V. | B49: 0 | C49: 0 | D49: 288179 | E49: 0 | F49: =B49+C49+D49-E49 -> 288179 | G49: 0.15 | H49: 21613 | I49: =IF(E49>0,0,F49-H49) -> 266566
A50: GRAND TOTAL | B50: =B8+B9+B10+B11+B12+B13+B14+B15+B16+B17+B18+B19+B20+B21+B22+B23+B24+B25+B26+B27+B28+B29+B31+B33+B34+B35+B36+B37+B38+B39+B40+B41+B42+B43+B44+B45+B46+B47+B48+B49 -> 4619487.2 | C50: =C8+C9+C10+C11+C12+C13+C14+C15+C16+C17+C18+C19+C20+C21+C22+C23+C24+C25+C26+C27+C28+C29+C31+C33+C34+C35+C36+C37+C38+C39+C40+C41+C42+C43+C44+C45+C46+C47+C48+C49 -> 348572 | D50: =D8+D9+D10+D11+D12+D13+D14+D15+D16+D17+D18+D19+D20+D21+D22+D23+D24+D25+D26+D27+D28+D29+D31+D33+D34+D35+D36+D37+D38+D39+D40+D41+D42+D43+D44+D45+D46+D47+D48+D49 -> 687548 | E50: =E8+E9+E10+E11+E12+E13+E14+E15+E16+E17+E18+E19+E20+E21+E22+E23+E24+E25+E26+E27+E28+E29+E31+E33+E34+E35+E36+E37+E38+E39+E40+E41+E42+E43+E44+E45+E46+E47+E48+E49 -> 183195 | F50: =F8+F9+F10+F11+F12+F13+F14+F15+F16+F17+F18+F19+F20+F21+F22+F23+F24+F25+F26+F27+F28+F29+F31+F33+F34+F35+F36+F37+F38+F39+F40+F41+F42+F43+F44+F45+F46+F47+F48+F49 -> 5472412.2 | H50: =H8+H9+H10+H11+H12+H13+H14+H15+H16+H17+H18+H19+H20+H21+H22+H23+H24+H25+H26+H27+H28+H29+H31+H33+H34+H35+H36+H37+H38+H39+H40+H41+H42+H43+H44+H45+H46+H47+H48+H49 -> 778873 | I50: =I8+I9+I10+I11+I12+I13+I14+I15+I16+I17+I18+I19+I20+I21+I22+I23+I24+I25+I26+I27+I28+I29+I31+I33+I34+I35+I36+I37+I38+I39+I40+I41+I42+I43+I44+I45+I46+I47+I48+I49 -> 4687552.5
A51: Add: Gold (non-depreciable) | I51: 154727
A52: Net Block as per Balance Sheet (Note 8) | I52: =I50+I51 -> 4842279.5
A54: Tata 709 LPT Truck sold during the year for ₹1,83,195; depreciation on the balance WDV charged and the asset removed from the block (book loss of ₹5,986.69 on the asset).
...

Sheet Sch B - Borrowings
A1: GUPTA AGENCY
A2: (Proprietor: Subhash Chander Gupta)
A3: H-129, Mohammadpur Village, New Delhi – 110066 | PAN: ABZPG3547J | GSTIN: 07ABZPG3547J1Z3
A4: Schedule B – Lender-wise Borrowings as on 31st March 2026
J5: (Amount in ₹)
A6: S.No | B6: Lender | C6: Loan A/c No. | D6: Borrower | E6: Nature | F6: Secured / Unsecured | G6: As per Books 31.03.2026 | H6: As per Lender Statement | I6: Difference | J6: Interest FY 2025-26
A7: 1 | B7: Axis Bank Ltd. | C7: SBR012613028038 | D7: Subhash Chand Gupta | E7: Loan Against Property | F7: Secured | G7: 11437844 | H7: 11437844 | I7: =G7-H7 -> 0 | J7: 614561
A8: 2 | B8: Cholamandalam Inv. & Fin. Co. | C8: HE01XBVO0000058448 | D8: Subhash Chander Gupta | E8: Home Equity Loan (closed – Axis takeover) | F8: Secured | G8: 0 | H8: 0 | I8: =G8-H8 -> 0 | J8: 405219
A9: 3 | B9: ICICI Bank Ltd. | C9: LADEL00045571235 | D9: Subhash Chand Gupta | E9: Auto Loan (Car) | F9: Secured | G9: 37765 | H9: 37765 | I9: =G9-H9 -> 0 | J9: 20055
A10: 4 | B10: Bajaj Finance Ltd. | C10: P401PPS49835125 | D10: Gupta Agency | E10: SME Business Loan | F10: Unsecured | G10: 3875890 | H10: 3875890 | I10: =G10-H10 -> 0 | J10: 323638
A11: 5 | B11: Poonawalla Fincorp Ltd. | C11: BLUDLDEBL_000019434458 | D11: Gupta Agency | E11: Business Loan | F11: Unsecured | G11: 2708364 | H11: 2708364 | I11: =G11-H11 -> 0 | J11: 235895
A12: 6 | B12: SMFG India Credit Co. Ltd. | C12: 218502412234677 | D12: Gupta Agency | E12: Business Instalment Loan | F12: Unsecured | G12: 2700074 | H12: 2700073.5 | I12: =G12-H12 -> 0.49 | J12: 241757.51
A13: 7 | B13: HDB Financial Services Ltd. | C13: 61294244 / 61618043 / 61620994 | D13: Gupta Agency | E13: Commercial Vehicle Loans (3) | F13: Secured | G13: 1954440 | H13: 1954440 | I13: =G13-H13 -> 0 | J13: 289983
A14: 8 | B14: State Bank of India | C14: 41481610274 | D14: Ravi Kant Gupta | E14: Home Loan | F14: Secured | G14: 28504956 | H14: 28331996 | I14: =G14-H14 -> 172960 | J14: 2154562
A15: 9 | B15: Muthoot Finance Ltd. | C15: 00012/MBE/000012 | D15: Subhash Chand Gupta | E15: Gold Loan (bullet) | F15: Secured | G15: 6897966 | H15: 6950000 | I15: =G15-H15 -> -52034 | J15: 0
B16: TOTAL (Term Loans) | G16: =SUM(G7:G15) -> 58117299 | H16: =SUM(H7:H15) -> 57996373 | I16: =SUM(I7:I15) -> 120926.49 | J16: =SUM(J7:J15) -> 4285670.5
B18: Other borrowings as per books: Central Bank of India CC ₹1,93,46,532 (Note 4); unsecured loans from friends & relatives ₹23,13,951 (Note 3).
B19: Current maturities (next 12 months) as per lender schedules: ₹1,05,79,965 (incl. Muthoot gold loan ₹69,50,000 – bullet repayment).
B22: As per our report of even date attached | H22: For and on behalf of
B23: For G R B & Co. | H23: GUPTA AGENCY
B24: Chartered Accountants
B25: FRN: 040755N
B31: CA Roopali Garg
B32: Partner | H32: Subhash Chander Gupta
B33: M. No. 570376 | H33: Proprietor
B34: UDIN: ____________________
B35: Place: Delhi
B36: Date: 25/09/2026

Sheet Sch C - GST
A1: GUPTA AGENCY
A2: (Proprietor: Subhash Chander Gupta)
A3: H-129, Mohammadpur Village, New Delhi – 110066 | PAN: ABZPG3547J | GSTIN: 07ABZPG3547J1Z3
A4: Schedule C – Month-wise GST Summary as per Returns (FY 2025-26)
M5: (Amount in ₹)
B6: Outward Supplies (GSTR-1) | I6: Input Tax Credit (GSTR-3B)
A7: Month | B7: Taxable Value | C7: Nil / Exempt | D7: IGST | E7: CGST | F7: SGST | G7: Cess | H7: Total Sales | I7: IGST | J7: CGST | K7: SGST | L7: Cess | M7: RCM ITC (CGST+SGST)
A8: Apr-25 | B8: 18642607 | C8: 215720 | D8: 0 | E8: 2182722.4 | F8: 2182722.4 | G8: 1576420.8 | H8: =B8+C8 -> 18858327 | I8: 4101141.5 | J8: 9478.68 | K8: 9478.68 | L8: 1485208.4 | M8: 0
A9: May-25 | B9: 10737512 | C9: 212450 | D9: 0 | E9: 1352864.4 | F9: 1352864.4 | G9: 1050018.5 | H9: =B9+C9 -> 10949962 | I9: 2404567.8 | J9: 17645.28 | K9: 17645.28 | L9: 954471.02 | M9: 0
A10: Jun-25 | B10: 18198867 | C10: 191150 | D10: 0 | E10: 2249749.5 | F10: 2249749.5 | G10: 1716376.9 | H10: =B10+C10 -> 18390017 | I10: 3565391.9 | J10: 13518.8 | K10: 13518.8 | L10: 1399843.7 | M10: 0
A11: Jul-25 | B11: 10653790 | C11: 198760 | D11: 0 | E11: 1345581.1 | F11: 1345581.1 | G11: 1043528.8 | H11: =B11+C11 -> 10852550 | I11: 2554868.9 | J11: 5077.05 | K11: 5077.05 | L11: 1032248.9 | M11: 0
A12: Aug-25 | B12: 9083304 | C12: 211400 | D12: 0 | E12: 1108962.3 | F12: 1108962.3 | G12: 834074.19 | H12: =B12+C12 -> 9294704 | I12: 2221478.4 | J12: 13792.46 | K12: 13792.46 | L12: 821508.23 | M12: 0
A13: Sep-25 | B13: 9040419.8 | C13: 96910 | D13: 0 | E13: 1174450.7 | F13: 1174450.7 | G13: 503564.86 | H13: =B13+C13 -> 9137329.8 | I13: 2054365.4 | J13: 36561.56 | K13: 36561.56 | L13: 503564.88 | M13: 0
A14: Oct-25 | B14: 10449276 | C14: 224780 | D14: 0 | E14: 1644312.7 | F14: 1644312.7 | G14: 0 | H14: =B14+C14 -> 10674056 | I14: 3164388.8 | J14: 43913.39 | K14: 43913.39 | L14: 0 | M14: 0
A15: Nov-25 | B15: 7914236.5 | C15: 255360 | D15: 0 | E15: 1259184.8 | F15: 1259184.8 | G15: 0 | H15: =B15+C15 -> 8169596.5 | I15: 3296197.4 | J15: 3507.94 | K15: 3507.94 | L15: 0 | M15: 0
A16: Dec-25 | B16: 5932243.7 | C16: 172100 | D16: 342.86 | E16: 974411.43 | F16: 974411.43 | G16: 0 | H16: =B16+C16 -> 6104343.7 | I16: 1094567.4 | J16: 16522.31 | K16: 16522.31 | L16: 0 | M16: 15289.2
A17: Jan-26 | B17: 9974903.8 | C17: 250150 | D17: 0 | E17: 1664886.8 | F17: 1664886.8 | G17: 0 | H17: =B17+C17 -> 10225054 | I17: 3262120.3 | J17: 38611.07 | K17: 38611.07 | L17: 0 | M17: 15289.2
A18: Feb-26 | B18: 11561722 | C18: 268360 | D18: 0 | E18: 1865032.6 | F18: 1865032.6 | G18: 0 | H18: =B18+C18 -> 11830082 | I18: 3869446.8 | J18: 38333.53 | K18: 38333.53 | L18: 0 | M18: 15289.2
A19: Mar-26 | B19: 10389618 | C19: 250065 | D19: 10674.89 | E19: 1757832.3 | F19: 1757832.3 | G19: 0 | H19: =B19+C19 -> 10639683 | I19: 4300849.6 | J19: 44467.08 | K19: 44467.08 | L19: 0 | M19: 15289.2
A20: TOTAL | B20: =SUM(B8:B19) -> 1.325785e+08 | C20: =SUM(C8:C19) -> 2547205 | D20: =SUM(D8:D19) -> 11017.75 | E20: =SUM(E8:E19) -> 18579991 | F20: =SUM(F8:F19) -> 18579991 | G20: =SUM(G8:G19) -> 6723984 | H20: =SUM(H8:H19) -> 1.351257e+08 | I20: =SUM(I8:I19) -> 35889384 | ... M20: =SUM(M8:M19) -> 61156.8
A22: Reconciliation
A23: Total Sales as per GST Returns | E23: =H20 -> 1.351257e+08
A24: Revenue from Operations as per Books (Note 16) | E24: =Notes!B150 -> 1.351257e+08
A25: Difference | E25: =E23-E24 -> 0
A27: As per GSTR-3B annual summary: Total output tax ₹4,38,94,983.60 (incl. cess ₹67,23,983.97); RCM tax ₹61,156.80; net ITC ₹4,27,05,737.73; tax paid in cash ₹1,10,928; no interest or late fee.
A28: GST payable of ₹35,26,340 and GST input of ₹43,89,784 as at 31.03.2026 are shown in Notes 6 and 15 respectively.
A31: As per our report of even date attached | I31: For and on behalf of
A32: For G R B & Co. | I32: GUPTA AGENCY
A33: Chartered Accountants
A34: FRN: 040755N
A40: CA Roopali Garg
A41: Partner | I41: Subhash Chander Gupta
A42: M. No. 570376 | I42: Proprietor
A43: UDIN: ____________________
A44: Place: Delhi
A45: Date: 25/09/2026

Sheet Sch D - TDS
A1: GUPTA AGENCY
A2: (Proprietor: Subhash Chander Gupta)
A3: H-129, Mohammadpur Village, New Delhi – 110066 | PAN: ABZPG3547J | GSTIN: 07ABZPG3547J1Z3
A4: Schedule D – TDS Deducted, Deposited & Returns Filed (FY 2025-26) | TAN: DELS55914F
H5: (Amount in ₹)
A6: A. Section-wise TDS
A7: S.No | B7: Nature of Payment / Deductee | C7: Section | D7: Rate | E7: Amount Paid / Credited* | F7: TDS Deducted | G7: TDS Deposited | H7: Interest / Fee
A8: 1 | B8: Purchase of Goods (Moon Beverages Ltd.) | C8: 194Q | D8: 0.001 | E8: 124325000 | F8: 124325 | G8: 124325 | H8: 0
A9: 2 | B9: Rent – Land / Building (Kanwar Singh) | C9: 194I | D9: 0.1 | E9: 1019390 | F9: 101939 | G9: 101939 | H9: 0
A10: 3 | B10: Professional / Technical Fees (Nazma Praveen) | C10: 194J | D10: 0.1 | E10: 78000 | F10: 7800 | G10: 7800 | H10: 0
B11: TOTAL | E11: =SUM(E8:E10) -> 125422390 | F11: =SUM(F8:F10) -> 234064 | G11: =SUM(G8:G10) -> 234064 | H11: =SUM(H8:H10) -> 0
B12: * Amount paid/credited derived from TDS at the applicable rate; for 194Q it is purchases in excess of ₹50 lakh threshold.
A15: B. Quarterly TDS Returns (Form 26Q)
A16: Qtr | B16: Period | C16: Filed on | D16: Due Date | E16: Status | F16: Amount Paid / Credited | G16: TDS Deducted | H16: TDS Deposited
A17: Q1 | B17: 01-04-2025 to 30-06-2025 | C17: 45867 | D17: 45869 | E17: On Time | F17: 41180303 | G17: 68338.02 | H17: 68377
A18: Q2 | B18: 01-07-2025 to 30-09-2025 | C18: 45938 | D18: 45961 | E18: On Time | F18: 27239229 | G18: 54396.91 | H18: 54431
A19: Q3 | B19: 01-10-2025 to 31-12-2025 | C19: 46041 | D19: 46053 | E19: On Time | F19: 23210793 | G19: 50368.52 | H19: 50402
A20: Q4 | B20: 01-01-2026 to 31-03-2026 | C20: 46147 | D20: 46173 | E20: On Time | F20: 33663384 | G20: 60820.99 | H20: 60855
B21: TOTAL | F21: =SUM(F17:F20) -> 1.2529371e+08 | G21: =SUM(G17:G20) -> 233924.44 | H21: =SUM(H17:H20) -> 234065
A24: C. TDS Payable as on 31.03.2026 (Note 6)
A25: S.No | B25: Particulars | C25: Section | D25: Month of Deduction | E25: Deposited on | F25: Due Date | G25: Amount | H25: Status
A26: 1 | B26: TDS payable | C26: 194Q | D26: Mar-2026 | E26: 05-04-2026 | F26: 30-04-2026 | G26: 13107 | H26: Paid on time
A27: 2 | B27: TDS payable | C27: 194I | D27: Mar-2026 | E27: 05-04-2026 | F27: 30-04-2026 | G27: 8495 | H27: Paid on time
A28: 3 | B28: TDS payable | C28: 194J | D28: Mar-2026 | E28: 05-04-2026 | F28: 30-04-2026 | G28: 650 | H28: Paid on time
B29: TOTAL | G29: =SUM(G26:G28) -> 22252
A32: D. Acknowledgement Details – Form 26Q (e-Filing)
A33: Qtr | B33: Quarterly Statement Receipt No. | C33: FVU Version | D33: Token / RRR No. | E33: Form 27A File Hash | G33: Verified By (PAN) | H33: Capacity
A34: Q1 | B34: 487957680290725 | C34: 9.2 | D34: 770000330360251 | E34: 00000000000207264790 | G34: ABZPG3547J | H34: PROPRIETOR
A35: Q2 | B35: 973941750081025 | C35: 9.2 | D35: 770000339737215 | E35: 00000000000136963266 | G35: ABZPG3547J | H35: PROPRIETOR
A36: Q3 | B36: 254956650190126 | C36: 9.2 | D36: 770000358993810 | E36: 00000000000121516827 | G36: ABZPG3547J | H36: PROPRIETOR
A37: Q4 | B37: 809077460050526 | C37: 9.4 | D37: 770000375250735 | E37: 00000000000155197601 | G37: ABZPG3547J | H37: PROPRIETOR
B39: All TDS deposited and 26Q returns filed within due dates; no interest u/s 201(1A) or fee u/s 234E. No correction statement filed for FY 2025-26.
B42: As per our report of even date attached | E42: For and on behalf of
B43: For G R B & Co. | E43: GUPTA AGENCY
B44: Chartered Accountants
B45: FRN: 040755N
B51: CA Roopali Garg
B52: Partner | E52: Subhash Chander Gupta
B53: M. No. 570376 | E53: Proprietor
B54: UDIN: ____________________
...
