Workbook

Sheet Balance Sheet
B2: =Inputs!$B$4 -> HEMRAJ NARANG AND SONS PRIVATE LIMITED
B3: =Inputs!$B$5 -> B-49, Central Market, Mad, Dr. Ambedkar Nagar, Dr. Ambedkar Nagar (South Delhi), New Delhi, South Delhi- 110062, Delhi
B4: ="Corporate Identity Number: "&Inputs!$B$6 -> Corporate Identity Number: U56102DL2023PTC421829
B6: Balance Sheet as at 31 March, 2026
E8: (Rupees in hundreds)
B9: Particulars | C9: Note No. | D9: As at 31 March, 2026 | E9: As at 31 March, 2025
B10: I. EQUITY AND LIABILITIES
B11: (1) Shareholders’ funds
B12: (a) Share capital | C12: 1 | D12: =Notes!C10 -> 1000 | E12: =Notes!D10 -> 1000
B13: (b) Reserves and surplus | C13: 2 | D13: =Notes!C37 -> -2777.987 | E13: =Notes!D37 -> -900
D14: =SUM(D12:D13) -> -1777.987 | E14: =SUM(E12:E13) -> 100
B15: (2) Non-current liabilities
B16: (a) Long-term borrowings | C16: 3 | D16: =Notes!C43 -> 6000 | E16: =Notes!D43 -> 0
D17: =SUM(D16:D16) -> 6000 | E17: =SUM(E16:E16) -> 0
B18: (3) Current liabilities
B19: (a) Trade payables | C19: 4
B20: Total outstanding dues of micro and small enterprises | D20: =Notes!C50 -> 0 | E20: =Notes!D50 -> 0
B21: Total outstanding dues of creditors other than micro and small enterprises | D21: =Notes!C51 -> 0 | E21: =Notes!D51 -> 0
B22: (b) Other current liabilities | C22: 5 | D22: =Notes!C60 -> 1150 | E22: =Notes!D60 -> 400
B23: (c) Short-term provisions | C23: 6 | D23: =Notes!C67 -> 0 | E23: =Notes!D67 -> 0
D24: =SUM(D20:D23) -> 1150 | E24: =SUM(E20:E23) -> 400
B25: TOTAL | D25: =D14+D17+D24 -> 5372.013 | E25: =E14+E17+E24 -> 500
B27: II. ASSETS
B28: (1) Non-current assets
B29: (a) Long-term loans and advances | C29: 7 | D29: =Notes!C73 -> 4800 | E29: =Notes!D73 -> 0
D30: =SUM(D29:D29) -> 4800 | E30: =SUM(E29:E29) -> 0
B31: (2) Current assets
B32: (a) Cash and cash equivalents | C32: 8 | D32: =Notes!C81 -> 572.013 | E32: =Notes!D81 -> 500
D33: =SUM(D32:D32) -> 572.013 | E33: =SUM(E32:E32) -> 500
B34: TOTAL | D34: =D30+D33 -> 5372.013 | E34: =E30+E33 -> 500
B36: Check: Total liabilities – Total assets (should be zero) | D36: =ROUND(D25-D34,2) -> 0 | E36: =ROUND(E25-E34,2) -> 0
B38: Material accounting policies | C38: A
B39: Notes on financial statements | C39: 1-18
B40: The notes referred to above form an integral part of the financial statements.
B42: As per our report of even date attached
B44: For and on behalf of | D44: For and on behalf of the Board of Directors
B45: =Inputs!$B$8 -> G R B & CO
B46: Chartered Accountants
B47: ="FRN No. "&Inputs!$B$9 -> FRN No. 040755N
B54: =Inputs!$B$10 -> Roopali Garg | D54: =Inputs!$B$13 -> MANSHU NARANG | E54: =Inputs!$B$15 -> LOKESH NARANG
...

Sheet Profit and Loss
B2: =Inputs!$B$4 -> HEMRAJ NARANG AND SONS PRIVATE LIMITED
B3: =Inputs!$B$5 -> B-49, Central Market, Mad, Dr. Ambedkar Nagar, Dr. Ambedkar Nagar (South Delhi), New Delhi, South Delhi- 110062, Delhi
B4: ="Corporate Identity Number: "&Inputs!$B$6 -> Corporate Identity Number: U56102DL2023PTC421829
B6: Statement of Profit and Loss for the year ended 31 March, 2026
E8: (Rupees in hundreds)
B9: Particulars | C9: Note No. | D9: Year ended 31 March, 2026 | E9: Year ended 31 March, 2025
B11: I. Revenue from operations | C11: 9 | D11: =Notes!C86 -> 0 | E11: =Notes!D86 -> 0
B12: II. Other income | C12: 10 | D12: =Notes!C91 -> 0 | E12: =Notes!D91 -> 0
B13: III. Total income (I + II) | D13: =SUM(D11:D12) -> 0 | E13: =SUM(E11:E12) -> 0
B15: IV. Expenses
B16: Employee benefits expense | D16: 0 | E16: 0
B17: Finance costs | C17: 11 | D17: =Notes!C96 -> 0 | E17: =Notes!D96 -> 0
B18: Depreciation and amortisation expense | D18: 0 | E18: 0
B19: Other expenses | C19: 12 | D19: =Notes!C106 -> 1877.987 | E19: =Notes!D106 -> 400
B20: Total expenses (IV) | D20: =SUM(D16:D19) -> 1877.987 | E20: =SUM(E16:E19) -> 400
B22: V. Profit / (Loss) before tax (III - IV) | D22: =D13-D20 -> -1877.987 | E22: =E13-E20 -> -400
B24: VI. Tax expense
B25: (1) Current tax | D25: 0 | E25: 0
B26: (2) Deferred tax | D26: 0 | E26: 0
D27: =SUM(D25:D26) -> 0 | E27: =SUM(E25:E26) -> 0
B29: VII. Profit / (Loss) for the year (V - VI) | D29: =D22-D27 -> -1877.987 | E29: =E22-E27 -> -400
B31: VIII. Earnings per equity share (face value Rs 10 each)
B32: Basic (Rs) | C32: 13 | D32: =Notes!C120 -> -18.78 | E32: =Notes!D120 -> -4
B33: Diluted (Rs) | C33: 13 | D33: =Notes!C120 -> -18.78 | E33: =Notes!D120 -> -4
B35: Material accounting policies | C35: A
B36: Notes on financial statements | C36: 1-18
B37: The notes referred to above form an integral part of the financial statements.
B39: As per our report of even date attached
B41: For and on behalf of | D41: For and on behalf of the Board of Directors
B42: =Inputs!$B$8 -> G R B & CO
B43: Chartered Accountants
B44: ="FRN No. "&Inputs!$B$9 -> FRN No. 040755N
B51: =Inputs!$B$10 -> Roopali Garg | D51: =Inputs!$B$13 -> MANSHU NARANG | E51: =Inputs!$B$15 -> LOKESH NARANG
B52: ="Proprietor M.No. "&Inputs!$B$11 -> Proprietor M.No. 570376 | D52: (Director) | E52: (Director)
B53: ="UDIN: "&Inputs!$B$12 -> UDIN: | D53: ="DIN: "&Inputs!$B$14 -> DIN: 10368816 | E53: ="DIN: "&Inputs!$B$16 -> DIN: 10368815
B54: ="Place : "&Inputs!$B$17 -> Place : New Delhi
B55: ="Date : "&Inputs!$B$18 -> Date : 15th Sep, 2026

Sheet Cash Flow
B2: =Inputs!$B$4 -> HEMRAJ NARANG AND SONS PRIVATE LIMITED
B3: =Inputs!$B$5 -> B-49, Central Market, Mad, Dr. Ambedkar Nagar, Dr. Ambedkar Nagar (South Delhi), New Delhi, South Delhi- 110062, Delhi
B4: ="Corporate Identity Number: "&Inputs!$B$6 -> Corporate Identity Number: U56102DL2023PTC421829
B6: Cash Flow Statement for the year ended 31 March, 2026
E8: (Rupees in hundreds)
C9: Particulars | D9: Year ended 31 March, 2026 | E9: Year ended 31 March, 2025 | G9: Balances as at 31.03.2024 (per FY 24-25 audited FS)
G10: Other current assets | H10: 200
B11: A. | C11: Cash flow from operating activities | G11: Other current liabilities | H11: 200
C12: Profit / (Loss) before tax | D12: ='Profit and Loss'!D22 -> -1877.987 | E12: ='Profit and Loss'!E22 -> -400 | G12: Long-term loans & advances | H12: 0
C13: Adjustments for: Depreciation / Finance costs | D13: ='Profit and Loss'!D18+'Profit and Loss'!D17 -> 0 | E13: ='Profit and Loss'!E18+'Profit and Loss'!E17 -> 0
C14: Operating profit / (loss) before working capital changes | D14: =D12+D13 -> -1877.987 | E14: =E12+E13 -> -400
C15: Adjustments for working capital:
C16: (Increase) / decrease in long-term loans & advances (security deposit) | D16: ='Balance Sheet'!E29-'Balance Sheet'!D29 -> -4800 | E16: =H12-'Balance Sheet'!E29 -> 0
C17: (Increase) / decrease in other current assets | D17: 0 | E17: =H10-0 -> 200
C18: Increase / (decrease) in trade payables & other current liabilities | D18: =('Balance Sheet'!D20+'Balance Sheet'!D21+'Balance Sheet'!D22)-('Balance Sheet'!E20+'Balance Sheet'!E21+'Balance Sheet'!E22) -> 750 | E18: =('Balance Sheet'!E20+'Balance Sheet'!E21+'Balance Sheet'!E22)-H11 -> 200
C19: Cash generated from / (used in) operations | D19: =SUM(D14,D16:D18) -> -5927.987 | E19: =SUM(E14,E16:E18) -> 0
C20: Direct taxes paid (net) | D20: 0 | E20: 0
C21: Net cash from / (used in) operating activities (A) | D21: =D19+D20 -> -5927.987 | E21: =E19+E20 -> 0
B23: B. | C23: Cash flow from investing activities
C24: Net cash from / (used in) investing activities (B) | D24: 0 | E24: 0
B26: C. | C26: Cash flow from financing activities
C27: Proceeds from issue of equity shares | D27: ='Balance Sheet'!D12-'Balance Sheet'!E12 -> 0 | E27: 0
C28: Proceeds from long-term borrowings (directors) | D28: ='Balance Sheet'!D16-'Balance Sheet'!E16 -> 6000 | E28: 0
C29: Net cash from / (used in) financing activities (C) | D29: =D27+D28 -> 6000 | E29: =E27+E28 -> 0
C31: Net increase / (decrease) in cash and cash equivalents (A+B+C) | D31: =D21+D24+D29 -> 72.013 | E31: =E21+E24+E29 -> 0
C32: Opening cash and cash equivalents | D32: ='Balance Sheet'!E32 -> 500 | E32: 500
C33: Closing cash and cash equivalents | D33: =D31+D32 -> 572.013 | E33: =E31+E32 -> 500
C34: Check vs Balance Sheet (should be zero) | D34: =ROUND(D33-'Balance Sheet'!D32,2) -> 0 | E34: =ROUND(E33-'Balance Sheet'!E32,2) -> 0
C36: Components of cash and cash equivalents
C37: Balance with banks in current account | D37: =Notes!C79 -> 72.013 | E37: =Notes!D79 -> 0
C38: Cash on hand | D38: =Notes!C80 -> 500 | E38: =Notes!D80 -> 500
C39: Total (refer note 8) | D39: =D37+D38 -> 572.013 | E39: =E37+E38 -> 500
C41: The above cash flow statement has been prepared under the Indirect Method as set out in AS 3 "Cash Flow Statements". (Note: being a small company u/s 2(85), the cash flow statement is optional u/s 2(40) – retain or delete as per auditor.)
C43: As per our report of even date attached
C45: For and on behalf of | D45: For and on behalf of the Board of Directors
C46: =Inputs!$B$8 -> G R B & CO
C47: Chartered Accountants
C48: ="FRN No. "&Inputs!$B$9 -> FRN No. 040755N
C55: =Inputs!$B$10 -> Roopali Garg | D55: =Inputs!$B$13 -> MANSHU NARANG | E55: =Inputs!$B$15 -> LOKESH NARANG
C56: ="Proprietor M.No. "&Inputs!$B$11 -> Proprietor M.No. 570376 | D56: (Director) | E56: (Director)
...

Sheet Policy
B1: =Inputs!$B$4 -> HEMRAJ NARANG AND SONS PRIVATE LIMITED
B2: ="CIN: "&Inputs!$B$6 -> CIN: U56102DL2023PTC421829
B4: A. MATERIAL ACCOUNTING POLICIES
B6: 1. Corporate information
B7: HEMRAJ NARANG AND SONS PRIVATE LIMITED (CIN U56102DL2023PTC421829) is a private limited company incorporated in India under the Companies Act, 2013. Its registered office is at B-49, Central Market, Mad, Dr. Ambedkar Nagar, Dr. Ambedkar Nagar (South Delhi), New Delhi, South Delhi- 110062, Delhi. The company is engaged in the business of preparing, selling and serving Indian and South Indian cuisine and related food and beverages, and operating restaurants, cafes, food delivery and catering services. The company had not commenced commercial operations up to 31 March, 2026.
B8: 2. Basis of preparation
B9: The financial statements are prepared under the historical cost convention on the accrual basis of accounting in accordance with Generally Accepted Accounting Principles in India (Indian GAAP), including the Accounting Standards specified under section 133 of the Companies Act, 2013 read with Rule 7 of the Companies (Accounts) Rules, 2014, and are presented in the format prescribed in Division I of Schedule III to the Act. The company is a Small and Medium-sized Company (SMC) and has availed the exemptions/relaxations available to it. All amounts are presented in Rupees in hundreds, rounded off to two decimals, unless otherwise stated.
B10: 2.1 Current / non-current classification
B11: Assets and liabilities are classified as current or non-current as per the criteria set out in Schedule III, based on the company's operating cycle, which has been determined as twelve months.
B12: 2.2 Use of estimates
B13: The preparation of financial statements requires management to make estimates and assumptions that affect the reported amounts of assets, liabilities, income and expenses and the disclosure of contingent liabilities. Actual results could differ from those estimates; revisions are recognised prospectively.
B14: 2.3 Revenue recognition
B15: Revenue from sale of food and beverages is recognised when the significant risks and rewards are transferred to the customer, net of GST and discounts. Other income is recognised on accrual basis.
B16: 2.4 Preliminary and pre-operative expenses
... B31: Cash and cash equivalents comprise cash on hand and balances with banks in current accounts, which are subject to insignificant risk of change in value.

Sheet Notes
B1: =Inputs!$B$4 -> HEMRAJ NARANG AND SONS PRIVATE LIMITED
B2: Notes to financial statements for the year ended 31 March, 2026
B4: 1. SHARE CAPITAL | D4: (Rupees in hundreds)
B5: Particulars | C5: As at 31 March, 2026 | D5: As at 31 March, 2025
B6: Authorised
B7: =TEXT(Inputs!$B$7,"#,##0")&" (10,000) Equity Shares of Rs.10 each" -> 10,000 (10,000) Equity Shares of Rs.10 each | C7: =Inputs!$B$7*10/100 -> 1000 | D7: 1000
B8: Issued, subscribed & paid up
B9: 10,000 (10,000) Equity Shares of Rs.10 each fully paid up | C9: =-SUMIF(TB!$C:$C,"SC",TB!$H:$H)/100 -> 1000 | D9: =-SUMIF(TB!$C:$C,"SC",TB!$I:$I)/100 -> 1000
B10: Total | C10: =SUM(C9:C9) -> 1000 | D10: =SUM(D9:D9) -> 1000
B12: Figures in bracket represent those of the previous year.
B14: 1.1 Reconciliation of number of shares outstanding
B15: Particulars | C15: No. (CY) | D15: Rs 100s (CY) | E15: No. (PY) | F15: Rs 100s (PY)
B16: Shares outstanding at the beginning of the year | C16: 10000 | D16: =C16*10/100 -> 1000 | E16: 10000 | F16: =E16*10/100 -> 1000
B17: Add: Shares issued during the year | C17: =ROUND(-SUMIF(TB!$C:$C,"SC",TB!$H:$H)/10-C16,0) -> 0 | D17: =C17*10/100 -> 0 | E17: 0 | F17: =E17*10/100 -> 0
B18: Less: Shares bought back during the year | C18: 0 | D18: 0 | E18: 0 | F18: 0
B19: Shares outstanding at the end of the year | C19: =C16+C17-C18 -> 10000 | D19: =D16+D17-D18 -> 1000 | E19: =E16+E17-E18 -> 10000 | F19: =F16+F17-F18 -> 1000
B21: 1.2 Terms / rights attached to equity shares
B22: The company has only one class of equity shares having a par value of Rs 10/- per share. Each holder of equity shares is entitled to one vote per share. In the event of liquidation of the company, the holders of equity shares will be entitled to receive remaining assets of the company after distribution of all preferential amounts, in proportion to the number of equity shares held by the shareholders.
B24: 1.3 Shareholders holding more than 5% shares / 1.4 Shareholding of promoters
B25: Name of shareholder / promoter | C25: No. of shares 31.03.2026 | D25: % holding | E25: No. of shares 31.03.2025 | F25: % holding
B26: MANSHU NARANG | C26: =-SUMIF(TB!$A:$A,"Manshu*Equity*",TB!$H:$H)/10 -> 5000 | D26: =C26/C$19 -> 0.5 | E26: =-SUMIF(TB!$A:$A,"Manshu*Equity*",TB!$I:$I)/10 -> 5000 | F26: =E26/E$19 -> 0.5
B27: LOKESH NARANG | C27: =-SUMIF(TB!$A:$A,"Lokesh*Equity*",TB!$H:$H)/10 -> 5000 | D27: =C27/C$19 -> 0.5 | E27: =-SUMIF(TB!$A:$A,"Lokesh*Equity*",TB!$I:$I)/10 -> 5000 | F27: =E27/E$19 -> 0.5
B28: Total | C28: =SUM(C26:C27) -> 10000 | D28: =SUM(D26:D27) -> 1 | E28: =SUM(E26:E27) -> 10000 | F28: =SUM(F26:F27) -> 1
B29: % change in promoter shareholding during the year: Nil (Previous year: Nil).
B30: 1.5 The company has not reserved any shares for issue under options, has not allotted any shares pursuant to contract without payment in cash, nor issued bonus shares or bought back shares during the period of five years immediately preceding the reporting date.
B32: 2. RESERVES & SURPLUS | D32: (Rupees in hundreds)
B33: Particulars | C33: As at 31 March, 2026 | D33: As at 31 March, 2025
B34: Surplus / (Deficit) in statement of profit & loss
B35: Balance at the beginning of the year | C35: =-SUMIF(TB!$C:$C,"RS-OPEN",TB!$H:$H)/100 -> -900 | D35: =-SUMIF(TB!$C:$C,"RS-OPEN",TB!$I:$I)/100 -> -500
B36: Add: Profit / (Loss) for the year | C36: ='Profit and Loss'!D29 -> -1877.987 | D36: ='Profit and Loss'!E29 -> -400
B37: Balance at the end of the year | C37: =SUM(C35:C36) -> -2777.987 | D37: =SUM(D35:D36) -> -900
B39: 3. LONG-TERM BORROWINGS | D39: (Rupees in hundreds)
B40: Particulars | C40: As at 31 March, 2026 | D40: As at 31 March, 2025
B41: Unsecured
B42: Loans from directors | C42: =-SUMIF(TB!$C:$C,"LTB-DIR",TB!$H:$H)/100 -> 6000 | D42: =-SUMIF(TB!$C:$C,"LTB-DIR",TB!$I:$I)/100 -> 0
B43: Total | C43: =SUM(C42:C42) -> 6000 | D43: =SUM(D42:D42) -> 0
B45: 3.1 Loans from directors (Mr. Lokesh Narang Rs 3,000 hundreds and Mr. Manshu Narang Rs 3,000 hundreds) are unsecured and interest-free. The directors have confirmed that the loans will not be recalled within twelve months from the balance sheet date; accordingly they are classified as non-current. The directors have furnished declarations that the amounts are not out of borrowed funds; hence these are not deposits under Rule 2(1)(c)(viii) of the Companies (Acceptance of Deposits) Rules, 2014.
B46: 3.2 There is no default in repayment of loans or interest as on the balance sheet date.
B48: 4. TRADE PAYABLES | D48: (Rupees in hundreds)
B49: Particulars | C49: As at 31 March, 2026 | D49: As at 31 March, 2025
...

Sheet Ratios
B1: =Inputs!$B$4 -> HEMRAJ NARANG AND SONS PRIVATE LIMITED
B2: 16. ANALYTICAL RATIOS (Schedule III) – figures in Rupees in hundreds
B4: Ratio | C4: Numerator | D4: Denominator | E4: 31.03.2026 | F4: 31.03.2025 | G4: % Change | H4: Reason for variance > 25% | J4: Workings | K4: 31.03.2026 | L4: 31.03.2025 | M4: 31.03.2024
B5: Current ratio (times) | C5: Current assets | D5: Current liabilities | E5: =IFERROR(K5/K6,"N.A.") -> 0.49740261 | F5: =IFERROR(L5/L6,"N.A.") -> 1.25 | G5: =IF(AND(ISNUMBER(E5),ISNUMBER(F5),F5<>0),(E5-F5)/ABS(F5),"N.A.") -> -0.60207791 | H5: Funds deployed in non-current rent deposit while expense payables increased. | J5: Current assets | K5: ='Balance Sheet'!D33 -> 572.013 | L5: ='Balance Sheet'!E33 -> 500 | M5: =500+200 -> 700
B6: Debt-equity ratio (times) | C6: Borrowings | D6: Total equity | E6: =IF(K7<=0,"Not meaningful",K8/K7) -> Not meaningful | F6: =IF(L7<=0,"Not meaningful",L8/L7) -> 0 | G6: =IF(AND(ISNUMBER(E6),ISNUMBER(F6),F6<>0),(E6-F6)/ABS(F6),"N.A.") -> N.A. | H6: Directors' loans taken during the year; net worth negative due to accumulated losses. | J6: Current liabilities | K6: ='Balance Sheet'!D24 -> 1150 | L6: ='Balance Sheet'!E24 -> 400 | M6: =200 -> 200
B7: Debt service coverage ratio (times) | C7: Earnings available for debt service | D7: Debt service | E7: N.A. | F7: N.A. | G7: =IF(AND(ISNUMBER(E7),ISNUMBER(F7),F7<>0),(E7-F7)/ABS(F7),"N.A.") -> N.A. | H7: No debt service obligation (interest-free loans, no repayment due). | J7: Total equity | K7: ='Balance Sheet'!D14 -> -1777.987 | L7: ='Balance Sheet'!E14 -> 100 | M7: =500 -> 500
B8: Return on equity (%) | C8: Profit after tax | D8: Average total equity | E8: =IF((K7+L7)/2<=0,"Not meaningful",K10/((K7+L7)/2)) -> Not meaningful | F8: =IF((L7+M7)/2<=0,"Not meaningful",L10/((L7+M7)/2)) -> -1.3333333 | G8: =IF(AND(ISNUMBER(E8),ISNUMBER(F8),F8<>0),(E8-F8)/ABS(F8),"N.A.") -> N.A. | H8: Average equity negative in current year; ratio not meaningful. | J8: Borrowings | K8: ='Balance Sheet'!D16 -> 6000 | L8: ='Balance Sheet'!E16 -> 0 | M8: =0 -> 0
B9: Inventory turnover ratio (times) | C9: Cost of goods sold | D9: Average inventory | E9: N.A. | F9: N.A. | G9: =IF(AND(ISNUMBER(E9),ISNUMBER(F9),F9<>0),(E9-F9)/ABS(F9),"N.A.") -> N.A. | H9: No inventory – operations not commenced. | J9: Revenue from operations | K9: ='Profit and Loss'!D11 -> 0 | L9: ='Profit and Loss'!E11 -> 0
B10: Trade receivables turnover ratio (times) | C10: Revenue from operations | D10: Average trade receivables | E10: N.A. | F10: N.A. | G10: =IF(AND(ISNUMBER(E10),ISNUMBER(F10),F10<>0),(E10-F10)/ABS(F10),"N.A.") -> N.A. | H10: No revenue / receivables. | J10: Profit after tax | K10: ='Profit and Loss'!D29 -> -1877.987 | L10: ='Profit and Loss'!E29 -> -400
B11: Trade payables turnover ratio (times) | C11: Purchases | D11: Average trade payables | E11: N.A. | F11: N.A. | G11: =IF(AND(ISNUMBER(E11),ISNUMBER(F11),F11<>0),(E11-F11)/ABS(F11),"N.A.") -> N.A. | H11: No purchases. | J11: EBIT (PBT + finance cost) | K11: ='Profit and Loss'!D22+'Profit and Loss'!D17 -> -1877.987 | L11: ='Profit and Loss'!E22+'Profit and Loss'!E17 -> -400
B12: Net capital turnover ratio (times) | C12: Revenue from operations | D12: Working capital | E12: N.A. | F12: N.A. | G12: =IF(AND(ISNUMBER(E12),ISNUMBER(F12),F12<>0),(E12-F12)/ABS(F12),"N.A.") -> N.A. | H12: No revenue from operations. | J12: Capital employed (Equity + Borrowings) | K12: =K7+K8 -> 4222.013 | L12: =L7+L8 -> 100
B13: Net profit ratio (%) | C13: Profit after tax | D13: Revenue from operations | E13: N.A. | F13: N.A. | G13: =IF(AND(ISNUMBER(E13),ISNUMBER(F13),F13<>0),(E13-F13)/ABS(F13),"N.A.") -> N.A. | H13: No revenue from operations.
B14: Return on capital employed (%) | C14: EBIT | D14: Capital employed | E14: =IF(K12<=0,"Not meaningful",K11/K12) -> -0.44480844 | F14: =IF(L12<=0,"Not meaningful",L11/L12) -> -4 | G14: =IF(AND(ISNUMBER(E14),ISNUMBER(F14),F14<>0),(E14-F14)/ABS(F14),"N.A.") -> 0.88879789 | H14: Increase in capital employed through directors' loans; higher pre-operative expenses.
B15: Return on investment (%) | C15: Income from investments | D15: Average investments | E15: N.A. | F15: N.A. | G15: =IF(AND(ISNUMBER(E15),ISNUMBER(F15),F15<>0),(E15-F15)/ABS(F15),"N.A.") -> N.A. | H15: No investments.

Sheet TB
A1: Trial Balance mapping – FY 2025-26 (Tally) with FY 2024-25 comparative (amounts in Rupees)
A2: Map Code column drives every note (SUMIF). Change a code to regroup a ledger.
A4: Ledger | B4: Tally Group | C4: Map Code | D4: 31.03.2026 Dr | E4: 31.03.2026 Cr | F4: 31.03.2025 Dr | G4: 31.03.2025 Cr | H4: Net 2026 (Dr+/Cr-) | I4: Net 2025 (Dr+/Cr-) | J4: Remark
A5: Lokesh Narang Equity Share Capital | B5: Capital Account | C5: SC | D5: 0 | E5: 50000 | F5: 0 | G5: 50000 | H5: =D5-E5 -> -50000 | I5: =F5-G5 -> -50000
A6: Manshu Narang Equity Share Capital | B6: Capital Account | C6: SC | D6: 0 | E6: 50000 | F6: 0 | G6: 50000 | H6: =D6-E6 -> -50000 | I6: =F6-G6 -> -50000 | J6: No change in share capital during the year
A7: Loan from Director Lokesh Narang | B7: Unsecured Loans | C7: LTB-DIR | D7: 0 | E7: 300000 | F7: 0 | G7: 0 | H7: =D7-E7 -> -300000 | I7: =F7-G7 -> 0 | J7: Classified long-term – confirm terms
A8: Loan from Director Manshu Narang | B8: Unsecured Loans | C8: LTB-DIR | D8: 0 | E8: 300000 | F8: 0 | G8: 0 | H8: =D8-E8 -> -300000 | I8: =F8-G8 -> 0
A9: Sundry Creditors | B9: Current Liabilities | C9: TP-OTH | D9: 0 | E9: 0 | F9: 0 | G9: 0 | H9: =D9-E9 -> 0 | I9: =F9-G9 -> 0 | J9: Nil balance (Dr 1,04,000 / Cr 1,04,000)
A10: Audit Fees Payable | B10: Expense Payables | C10: OCL-AUD | D10: 0 | E10: 50000 | F10: 0 | G10: 20000 | H10: =D10-E10 -> -50000 | I10: =F10-G10 -> -20000
A11: Expenses Payable | B11: Expense Payables | C11: OCL-EXP | D11: 0 | E11: 65000 | F11: 0 | G11: 20000 | H11: =D11-E11 -> -65000 | I11: =F11-G11 -> -20000 | J11: PY Rs 20,000 not shown in signed FY 24-25 BS (BS was short by Rs 20,000) – restated per TB opening
A12: Rent Security Deposit - Kalkaji | B12: Security Deposits | C12: LTLA-SD | D12: 480000 | E12: 0 | F12: 0 | G12: 0 | H12: =D12-E12 -> 480000 | I12: =F12-G12 -> 0 | J12: Non-current: deposit for leased premises
A13: Cash | B13: Cash-in-Hand | C13: CASH | D13: 50000 | E13: 0 | F13: 50000 | G13: 0 | H13: =D13-E13 -> 50000 | I13: =F13-G13 -> 50000
A14: YES BANK CA 6197 | B14: Bank Accounts | C14: BANK | D14: 7201.3 | E14: 0 | F14: 0 | G14: 0 | H14: =D14-E14 -> 7201.3 | I14: =F14-G14 -> 0
A15: Office Expenses | B15: Administrative Expenses | C15: EXP-OFF | D15: 62000 | E15: 0 | F15: 0 | G15: 0 | H15: =D15-E15 -> 62000 | I15: =F15-G15 -> 0
A16: Accounting Charges | B16: Professional Charges | C16: EXP-ACC | D16: 25000 | E16: 0 | F16: 10000 | G16: 0 | H16: =D16-E16 -> 25000 | I16: =F16-G16 -> 10000
A17: ROC Filing Fees | B17: Professional Charges | C17: EXP-ROC | D17: 20000 | E17: 0 | F17: 0 | G17: 0 | H17: =D17-E17 -> 20000 | I17: =F17-G17 -> 0
A18: Statutory Audit Fees | B18: Professional Charges | C18: EXP-AUD | D18: 30000 | E18: 0 | F18: 20000 | G18: 0 | H18: =D18-E18 -> 30000 | I18: =F18-G18 -> 20000
A19: POS Machine Charges | B19: Finance Costs (Tally) | C19: EXP-BANK | D19: 10798.7 | E19: 0 | F19: 0 | G19: 0 | H19: =D19-E19 -> 10798.7 | I19: =F19-G19 -> 0 | J19: Monthly rental of POS machine – shown under Other expenses (not a borrowing cost under AS 16)
A20: Miscellaneous Expenses | B20: Other Expenses | C20: EXP-MISC | D20: 40000 | E20: 0 | F20: 10000 | G20: 0 | H20: =D20-E20 -> 40000 | I20: =F20-G20 -> 10000
A21: Profit & Loss A/c (opening deficit) | B21: Profit & Loss A/c | C21: RS-OPEN | D21: 90000 | E21: 0 | F21: 50000 | G21: 0 | H21: =D21-E21 -> 90000 | I21: =F21-G21 -> 50000 | J21: Opening accumulated loss
A22: Total | D22: =SUM(D5:D21) -> 815000 | E22: =SUM(E5:E21) -> 815000 | F22: =SUM(F5:F21) -> 140000 | G22: =SUM(G5:G21) -> 140000 | H22: =SUM(H5:H21) -> 0 | I22: =SUM(I5:I21) -> 0 | J22: =IF(AND(ROUND(H22,2)=0,ROUND(I22,2)=0),"TB tallies","CHECK – TB not tallying") -> TB tallies
A24: FY 25-26 figures: closing balances of Tally TB 1-Apr-25 to 31-Mar-26. FY 24-25 figures: audited FS (Rs in hundreds ×100), restated for expenses payable as noted.

Sheet Inputs
A1: INPUTS – edit yellow cells; all statements pick these up
A3: Field | B3: Value | C3: Source / remark
A4: Company name | B4: HEMRAJ NARANG AND SONS PRIVATE LIMITED | C4: Per TB / PY FS
A5: Registered office | B5: B-49, Central Market, Mad, Dr. Ambedkar Nagar, Dr. Ambedkar Nagar (South Delhi), New Delhi, South Delhi- 110062, Delhi | C5: Per FY 24-25 audited FS (Kalkaji address is office address, not registered office)
A6: CIN | B6: U56102DL2023PTC421829 | C6: Per PY FS
A7: Authorised equity shares (Rs 10 each) – Number | B7: 10000 | C7: Confirmed – no increase in authorised capital
A8: Auditor firm | B8: G R B & CO | C8: Confirmed by client
A9: Auditor FRN | B9: 040755N
A10: Signing partner / proprietor | B10: Roopali Garg
A11: Membership No. | B11: 570376
A12: UDIN
A13: Director 1 | B13: MANSHU NARANG
A14: Director 1 DIN | B14: 10368816
A15: Director 2 | B15: LOKESH NARANG
A16: Director 2 DIN | B16: 10368815
A17: Place | B17: New Delhi
A18: Date of signing | B18: 15th Sep, 2026

Sheet Queries & Assumptions
B1: Points to confirm before finalisation
A3: # | B3: Point
A4: 1 | B4: Director loans: Rs 6,00,000 shown as Long-term borrowings. If repayable on demand → move to Short-term borrowings. Obtain directors' declaration under Rule 2(1)(c)(viii); report in DPT-3 if applicable.
A5: 2 | B5: Bank receipts: Bank receipts Rs 6,02,989.50 vs director loans Rs 6,00,000 + POS reversal Rs 989.50 – balance Rs 2,000 to be identified.
