Workbook

Sheet Balance Sheet
A1: M/S SHREE GANESHAY TRADERS
A2: (A Partnership Firm)
A3: 11/72 Dakshinpuri, New Delhi – 110062 | PAN: ACJFS4485L | MSME: UDYAM-DL-08-0038171
A4: Balance Sheet as at 31st March 2026
D5: (Amount in ₹)
A6: Particulars | B6: Note No. | C6: As at 31.03.2026 | D6: As at 31.03.2025
A7: I. SOURCES OF FUNDS (EQUITY AND LIABILITIES) | F7: Check (L – A)
A8: 1. Partners' Funds | F8: =C17-C28 -> 0 | G8: =D17-D28 -> 0
A9: Partners' Capital Accounts | B9: 1 | C9: =Notes!B14+Notes!C14 -> 6909910 | D9: =Notes!B23+Notes!C23 -> 4497442
A10: 2. Non-Current Liabilities
A11: Long-term Borrowings – Unsecured Loans | B11: 2 | C11: =Notes!B34 -> 1292767 | D11: =Notes!C34 -> 2117640
A12: 3. Current Liabilities
A13: Short-term Borrowings | B13: 3 | C13: =Notes!B41 -> 6696656 | D13: =Notes!C41 -> 6873191
A14: Trade Payables | B14: 4 | C14: =Notes!B47 -> 5465322 | D14: =Notes!C47 -> 5389635
A15: Other Current Liabilities | B15: 5 | C15: =Notes!B58 -> 166447 | D15: =Notes!C58 -> 154000
A16: Short-term Provisions | B16: 6 | C16: =Notes!B64 -> 73855 | D16: =Notes!C64 -> 60664
A17: TOTAL | C17: =C9+C11+C13+C14+C15+C16 -> 20604957 | D17: =D9+D11+D13+D14+D15+D16 -> 19092572
A19: II. APPLICATION OF FUNDS (ASSETS)
A20: 1. Non-Current Assets
A21: Property, Plant & Equipment | B21: 7 | C21: =Notes!B73 -> 1099931 | D21: =Notes!C73 -> 999649
A22: 2. Current Assets
A23: Inventories | B23: 8 | C23: =Notes!B79 -> 7941080 | D23: =Notes!C79 -> 7216498
A24: Trade Receivables | B24: 9 | C24: =Notes!B86 -> 9203319 | D24: =Notes!C86 -> 9242490
A25: Cash and Cash Equivalents | B25: 10 | C25: =Notes!B96 -> 1033047 | D25: =Notes!C96 -> 442243
A26: Short-term Loans and Advances | B26: 11 | C26: =Notes!B102 -> 1327580 | D26: =Notes!C102 -> 1104307
A27: Other Current Assets | B27: 12 | C27: =Notes!B109 -> 0 | D27: =Notes!C109 -> 87385
A28: TOTAL | C28: =C21+C23+C24+C25+C26+C27 -> 20604957 | D28: =D21+D23+D24+D25+D26+D27 -> 19092572
A30: Significant Accounting Policies and Notes to Accounts – Note 24. The notes and schedules form an integral part of the financial statements.
A33: As per our report of even date attached | C33: For and on behalf of
A34: For G R B & Co. | C34: M/S SHREE GANESHAY TRADERS
A35: Chartered Accountants
A36: FRN: 040755N
C40: ____________________
C41: Vivek Gupta
A42: CA Roopali Garg | C42: Partner
A43: Partner
A44: M. No. 570376 | C44: ____________________
A45: UDIN: ____________________ | C45: Durga Gupta
A46: Place: New Delhi | C46: Partner
A47: Date: ____________

Sheet Profit & Loss
A1: M/S SHREE GANESHAY TRADERS
A2: (A Partnership Firm)
A3: 11/72 Dakshinpuri, New Delhi – 110062 | PAN: ACJFS4485L | MSME: UDYAM-DL-08-0038171
A4: Statement of Profit & Loss for the year ended 31st March 2026
D5: (Amount in ₹)
A6: Particulars | B6: Note No. | C6: Year ended 31.03.2026 | D6: Year ended 31.03.2025
A7: I. Revenue from Operations | B7: 13 | C7: =Notes!B116 -> 1.2269396e+08 | D7: =Notes!C116 -> 1.1598781e+08
A8: II. Other Income | B8: 14 | C8: =Notes!B122 -> 4810 | D8: =Notes!C122 -> 14331.44
A9: III. Total Income (I + II) | C9: =C7+C8 -> 1.2269877e+08 | D9: =D7+D8 -> 1.1600214e+08
A11: IV. Expenses
A12: Purchases of Stock-in-Trade | B12: 15 | C12: =Notes!B128 -> 1.1112861e+08 | D12: =Notes!C128 -> 1.0288884e+08
A13: Changes in Inventories of Stock-in-Trade | B13: 16 | C13: =Notes!B135 -> -724582 | D13: =Notes!C135 -> -624286
A14: Direct Expenses | B14: 17 | C14: =Notes!B142 -> 883395.7 | D14: =Notes!C142 -> 834917.95
A15: Employee Benefit Expenses | B15: 18 | C15: =Notes!B150 -> 2304892.8 | D15: =Notes!C150 -> 3562278.7
A16: Remuneration to Partners | B16: 19 | C16: =Notes!B156 -> 1200000 | D16: =Notes!C156 -> 1200000
A17: Finance Costs | B17: 20 | C17: =Notes!B164 -> 585077.64 | D17: =Notes!C164 -> 105139.41
A18: Depreciation | B18: 21 | C18: =Notes!B170 -> 221860 | D18: =Notes!C170 -> 187108
A19: Other Expenses | B19: 22 | C19: =Notes!B191 -> 6014854.1 | D19: =Notes!C191 -> 6889559.9
A20: Total Expenses (IV) | C20: =SUM(C12:C19) -> 1.2161411e+08 | D20: =SUM(D12:D19) -> 1.1504356e+08
A22: V. Profit before Tax (III – IV) | C22: =C9-C20 -> 1084667.2 | D22: =D9-D20 -> 958579.84
A23: VI. Tax Expense – Current Tax | B23: 23 | C23: =Notes!B197 -> 338416 | D23: =Notes!C197 -> 299076.91
A24: VII. Profit after Tax (V – VI) | C24: =C22-C23 -> 746251.15 | D24: =D22-D23 -> 659502.93
A26: Profit after tax transferred to Partners' Capital Accounts:
A27: Vivek Gupta (80%) | C27: =ROUND(C24*0.8,2) -> 597000.92 | D27: =ROUND(D24*0.8,2) -> 527602.34
A28: Durga Gupta (20%) | C28: =C24-C27 -> 149250.23 | D28: =D24-D27 -> 131900.59
A30: Significant Accounting Policies and Notes to Accounts – Note 24. The notes and schedules form an integral part of the financial statements.
A33: As per our report of even date attached | C33: For and on behalf of
A34: For G R B & Co. | C34: M/S SHREE GANESHAY TRADERS
A35: Chartered Accountants
A36: FRN: 040755N
C40: ____________________
C41: Vivek Gupta
A42: CA Roopali Garg | C42: Partner
A43: Partner
A44: M. No. 570376 | C44: ____________________
A45: UDIN: ____________________ | C45: Durga Gupta
A46: Place: New Delhi | C46: Partner
A47: Date: ____________

Sheet Notes
A1: M/S SHREE GANESHAY TRADERS
A2: (A Partnership Firm)
A3: 11/72 Dakshinpuri, New Delhi – 110062 | PAN: ACJFS4485L | MSME: UDYAM-DL-08-0038171
A4: Notes forming part of the Financial Statements for the year ended 31st March 2026
C5: (Amount in ₹)
A6: Note 1: Partners' Capital Accounts
A7: Year ended 31.03.2026
A8: Particulars | B8: Vivek Gupta | C8: Durga Gupta
A9: Opening Balance | B9: 3092609 | C9: 1404833
A10: Add: Capital Introduced during the year | B10: 2006179 | C10: 615000
A11: Add: Share of Net Profit after Tax (80% : 20%) | B11: ='Profit & Loss'!C27 -> 597000.92 | C11: ='Profit & Loss'!C28 -> 149250.23
A12: Less: Drawings | B12: 954962 | C12: 0
A13: Add / (Less): Round Off | B13: 0.08 | C13: -0.23
A14: Closing Balance | B14: =B9+B10+B11-B12+B13 -> 4740827 | C14: =C9+C10+C11-C12+C13 -> 2169083
A16: Year ended 31.03.2025
A17: Particulars | B17: Vivek Gupta | C17: Durga Gupta
A18: Opening Balance | B18: 1594066 | C18: 687932
A19: Add: Capital Introduced during the year | B19: 970940.36 | C19: 585000
A20: Add: Share of Net Profit after Tax (80% : 20%) | B20: ='Profit & Loss'!D27 -> 527602.34 | C20: ='Profit & Loss'!D28 -> 131900.59
A21: Less: Drawings | B21: 0 | C21: 0
A22: Add / (Less): Round Off | B22: 0.3 | C22: 0.41
A23: Closing Balance | B23: =B18+B19+B20-B21+B22 -> 3092609 | C23: =C18+C19+C20-C21+C22 -> 1404833
A25: Profit after tax is shared between the partners in the ratio of 80:20 (Vivek Gupta : Durga Gupta). Capital balances are rounded off to the nearest rupee.
A28: Note 2: Long-term Borrowings – Unsecured Loans (Refer Schedule D)
A29: Particulars | B29: As at 31.03.2026 | C29: As at 31.03.2025
A30: V R Traders | B30: 1005500
A31: Ratan Agarwal | B31: 250000 | C31: 250000
A32: Bajaj Finance | B32: 37267 | C32: 83740
A33: Partners' Loan | B33: 0 | C33: 1783900
A34: Total | B34: =SUM(B30,B31,B32,B33) -> 1292767 | C34: =SUM(C30,C31,C32,C33) -> 2117640
A35: Previous year total of ₹21,17,640 is as per the audited Balance Sheet for FY 2024-25, which excluded the V R Traders balance of ₹5,500 shown therein.
A38: Note 3: Short-term Borrowings
A39: Particulars | B39: As at 31.03.2026 | C39: As at 31.03.2025
A40: Bank Overdraft – ICICI Bank Ltd. | B40: 6696656 | C40: 6873191
A41: Total | B41: =SUM(B40) -> 6696656 | C41: =SUM(C40) -> 6873191
A44: Note 4: Trade Payables (Refer Schedule C)
A45: Particulars | B45: As at 31.03.2026 | C45: As at 31.03.2025
A46: Sundry Creditors – Suppliers | B46: 5465322 | C46: 5389635
A47: Total | B47: =SUM(B46) -> 5465322 | C47: =SUM(C46) -> 5389635
A50: Note 5: Other Current Liabilities
...

Sheet Sch A - Depreciation
A1: M/S SHREE GANESHAY TRADERS
A2: (A Partnership Firm)
A3: 11/72 Dakshinpuri, New Delhi – 110062 | PAN: ACJFS4485L | MSME: UDYAM-DL-08-0038171
A4: Schedule A – Depreciation as per Section 32 of the Income-tax Act, 1961 (FY 2025-26, AY 2026-27)
I5: (Amount in ₹)
A6: Block of Assets | B6: WDV as on 01.04.2025 | C6: Additions ≥ 180 days | D6: Additions < 180 days | E6: Deletions | F6: Total as on 31.03.2026 | G6: Rate | H6: Depreciation for the year | I6: WDV as on 31.03.2026
A7: Plant & Machinery | B7: 1111411.9 | C7: 77043.84 | D7: 0 | E7: 0 | F7: =B7+C7+D7-E7 -> 1188455.7 | G7: 0.15 | H7: =ROUND((B7+C7-E7)*G7+D7*G7/2,0) -> 178268 | I7: =F7-H7 -> 1010187.7
A8: Computers (including Software) | B8: 42873.65 | C8: 57990 | D8: 0 | E8: 0 | F8: =B8+C8+D8-E8 -> 100863.65 | G8: 0.4 | H8: =ROUND((B8+C8-E8)*G8+D8*G8/2,0) -> 40345 | I8: =F8-H8 -> 60518.65
A9: Furniture and Fittings | B9: 32471 | C9: 0 | D9: 0 | E9: 0 | F9: =B9+C9+D9-E9 -> 32471 | G9: 0.1 | H9: =ROUND((B9+C9-E9)*G9+D9*G9/2,0) -> 3247 | I9: =F9-H9 -> 29224
A10: GRAND TOTAL | B10: =SUM(B7:B9) -> 1186756.5 | C10: =SUM(C7:C9) -> 135033.84 | D10: =SUM(D7:D9) -> 0 | E10: =SUM(E7:E9) -> 0 | F10: =SUM(F7:F9) -> 1321790.4 | H10: =SUM(H7:H9) -> 221860 | I10: =SUM(I7:I9) -> 1099930.4
A13: Details of Additions during the year
A14: Supplier | B14: Invoice No. | C14: Invoice Date | D14: Asset | E14: Block | F14: Taxable Value | G14: GST | H14: Capitalised | I14: Remarks
A15: Darshita Aashiyana Pvt. Ltd. | B15: DED4-198207 | C15: 30-07-2025 | D15: Mobile | E15: P&M | F15: 15250.85 | G15: 2745.15 | H15: 15250.85 | I15: ITC availed
A16: Pashupati Motors | B16: 10376AG25S1649 | C16: 31-07-2025 | D16: Bike | E16: P&M | F16: 47459.38 | G16: 13288.62 | H16: 60748 | I16: GST capitalised
A17: Pashupati Motors | B17: 10376BG25P562 | C17: 31-07-2025 | D17: Bike (accessories) | E17: P&M | F17: 885.59 | G17: 159.4 | H17: 1044.99 | I17: GST capitalised
A18: Clicktech Retail Pvt. Ltd. | B18: DEL4-1339336 | C18: 02-08-2025 | D18: Laptop | E18: Computers | F18: 49144.07 | G18: 8845.93 | H18: 57990 | I18: GST capitalised
A19: Total | F19: =SUM(F15:F18) -> 112739.89 | G19: =SUM(G15:G18) -> 25039.1 | H19: =SUM(H15:H18) -> 135033.84
A21: All additions were put to use for more than 180 days during the year; full rate of depreciation applied.
A24: As per our report of even date attached | F24: For and on behalf of
A25: For G R B & Co. | F25: M/S SHREE GANESHAY TRADERS
A26: Chartered Accountants
A27: FRN: 040755N
F31: ____________________
F32: Vivek Gupta
A33: CA Roopali Garg | F33: Partner
A34: Partner
A35: M. No. 570376 | F35: ____________________
A36: UDIN: ____________________ | F36: Durga Gupta
A37: Place: New Delhi | F37: Partner
A38: Date: ____________

Sheet Sch B - Debtors
A1: M/S SHREE GANESHAY TRADERS
A2: (A Partnership Firm)
A3: 11/72 Dakshinpuri, New Delhi – 110062 | PAN: ACJFS4485L | MSME: UDYAM-DL-08-0038171
A4: Schedule B – Sundry Debtors as on 31st March 2026
D5: (Amount in ₹)
A6: S. No. | B6: Name of Party | C6: Debit Balance | D6: Credit Balance
A7: 1 | B7: 7 SIS NORTH EAST STORE SAFDARJUNG | D7: 4548
A8: 2 | B8: 9 TEN STORE (SANGAM VIHAR) MADANGIR | C8: 1
A9: 3 | B9: A 2 Z MEDICOS MUNIRKA | C9: 520
A10: 4 | B10: A ONE TRADERS INA | C10: 12572
A11: 5 | B11: A&M GROCERY STORE BADARPUR,PRAHLA | C11: 7964
A12: 6 | B12: AAAS FOODS AND NATURES SOUL P LAGPAT NAGAR | C12: 4572
A13: 7 | B13: AAKASH MEDICARE (AMAR COLONY) TUGHLAKABAD | D13: 305
A14: 8 | B14: AAP KA BAZAR DWARIKA | D14: 4780
A15: 9 | B15: AAP KA BAZAR MAHAVIR ENCLAVE | C15: 20073
A16: 10 | B16: AB CRESCENT AMAR COLONY | C16: 9067
A17: 11 | B17: ACCELERATE PRODUCTS VENTURES KAILASH COLONY | C17: 16751
A18: 12 | B18: ACCELERATE PRODUCTX VENTURES LAJPAT NAGAR | C18: 14903
A19: 13 | B19: ADARSH MART (MALVIYA NGR.) MALVIYA NAGAR | C19: 450
A20: 14 | B20: ADISHTA MARKETING PVT.LTD SAFDARJUNG | C20: 5615
A21: 15 | B21: AGGARWAL & SONS'S (MADANGIR) MADANGIR | C21: 3902
A22: 16 | B22: AGGARWAL AGENCIES (HAUZ KHAS) HAUZ KHAS | C22: 1038
A23: 17 | B23: AGGARWAL DEPARTMENTAL (S.J.E) SAFDARJUNG | C23: 2
A24: 18 | B24: AGGARWAL GEN. STORE (A.NGR) HAUZ KHAS | C24: 73
A25: 19 | B25: AGGARWAL GROCERY(SANGAM VIHAR SANGAM VIHAR | C25: 262
A26: 20 | B26: AGGARWAL MEDICAL STORE PVT. TUGHLAKABAD | C26: 3272
A27: 21 | B27: AGGARWAL STORE (SANT NAGAR) GK-1, | D27: 996
A28: 22 | B28: AGGARWAL TRADERS (GP) GOVINDPURI | C28: 6
A29: 23 | B29: AHUJA STORE (JOR BAGH) INA | D29: 415
A30: 24 | B30: AIRPORT SERVICE STATION GK-2 | D30: 413
A31: 25 | B31: AKASH AYURVEDIC (MADANGIR) MADANGIR | C31: 847
A32: 26 | B32: ALL INDIA PHARMACY (NEHRU N) GARHI SANT NGR | D32: 229
A33: 27 | B33: ALLIED FRUIT & FLORISTS (KHAN INA | C33: 38633
A34: 28 | B34: ALOK D MART (V.KUNJ) VASANT KUNJ | C34: 1327
A35: 29 | B35: AMAR CHAND FOOD (BHOGAL) LAGPAT NAGAR | D35: 10211
A36: 30 | B36: AMBEY HEALTHCARE CHEMIST EAST OF KAILASH | C36: 2408
A37: 31 | B37: AMRIT STORE (MALVIYA NAGAR) MALVIYA NAGAR | D37: 2
A38: 32 | B38: AMRITSARIAN DI HATTI LAGPAT NAGAR | C38: 149
A39: 33 | B39: AMRITSARIAN DI HATTI (KOTLA) INA | C39: 1
A40: 34 | B40: ANAND GENERAL STORE (KHAN MKT INA | C40: 1406
...

Sheet Sch C - Creditors
A1: M/S SHREE GANESHAY TRADERS
A2: (A Partnership Firm)
A3: 11/72 Dakshinpuri, New Delhi – 110062 | PAN: ACJFS4485L | MSME: UDYAM-DL-08-0038171
A4: Schedule C – Sundry Creditors (Suppliers) as on 31st March 2026
D5: (Amount in ₹)
A6: S. No. | B6: Name of Party | C6: Debit Balance | D6: Credit Balance
B7: SUNDRY CREDITORS (SUPPLIERS)
A8: 1 | B8: A.J. FABRICATORS MAYAPURI | D8: 45000
A9: 2 | B9: ADIDEV TRADING COMPANY DELHI | D9: 2
A10: 3 | B10: ANAND ENTERPRISES. | C10: 1
A11: 4 | B11: ANIKA GRAH UDYOG FARIDABAD | D11: 671850
A12: 5 | B12: ANUJ KUMAR AND SONS | C12: 1550
A13: 6 | B13: ANUSHKA SALES & MARKETING | C13: 4838.37
A14: 7 | B14: ARCHIES LIMITED | C14: 0.36
A15: 8 | B15: ARORA WATCH & ELECTRONICS | D15: 0.44
A16: 9 | B16: ARUNA ENTERPRISES AZADPUR | C16: 46134.92
A17: 10 | B17: BANWARI LAL ARORA AND SONS. | D17: 408036
A18: 11 | B18: BRIDGE VENTURES PEERA GARHI | D18: 161036
A19: 12 | B19: CHAITANYA MARKETING AGENCY ROHINI | D19: 117404
A20: 13 | B20: CM FOODS 2020-21 NEW | C20: 20719
A21: 14 | B21: D.C.JOHAR & SONS PVT.LTD.MUMBA | C21: 1
A22: 15 | B22: DAS FOODTECH PVT.LTD. GUJRAT | C22: 489
A23: 16 | B23: DASS POLYMERS PVT. LTD. OKHLA | C23: 1
A24: 17 | B24: EUROTECH INFOSYS | C24: 27500
A25: 18 | B25: GUJARAT TEA PROCESSORS & PACKE | C25: 5878
A26: 19 | B26: HARI TRADING PALAM | C26: 196
A27: 20 | B27: HITKARY PHARMACY INDIA PVT LT HARYANA | D27: 31346
A28: 21 | B28: K C TRADERS & LOGISTICS DWARKA | C28: 3321
A29: 22 | B29: KEYA FOODS INTERNATIONAL DELHI | D29: 1577377.2
A30: 23 | B30: KRISHNA TYRE HOUSE KHANPUR | C30: 6000
A31: 24 | B31: MARG EXPERT | C31: 590.7
A32: 25 | B32: MARS INTERNATIONAL INDIA PVT HARYANA | C32: 774270.59
A33: 26 | B33: NARULA WINDSHIELD TRADERS SAKET | C33: 0.01
A34: 27 | B34: NOURISH ORGANIC PVT LTD HARYANA | C34: 6582
A35: 28 | B35: NUTRISUP SOLUTIONS JAMIA NAGAR | C35: 17064
A36: 29 | B36: OJAS TRADERS ROHINI | D36: 6226
A37: 30 | B37: P R MARKETING GHAZIABAD | C37: 1
A38: 31 | B38: PRAGARIKI | C38: 19715
A39: 32 | B39: PRATYUSH NISHA VENTURE PVT.LTD | D39: 1
A40: 33 | B40: PRINTER & SYSTEM SOLUTIONS NEHRU PLACE | C40: 12399.99
...

Sheet Sch D - Loans
A1: M/S SHREE GANESHAY TRADERS
A2: (A Partnership Firm)
A3: 11/72 Dakshinpuri, New Delhi – 110062 | PAN: ACJFS4485L | MSME: UDYAM-DL-08-0038171
A4: Schedule D – Unsecured Loans and Other Loans & Advances as on 31st March 2026
C5: (Amount in ₹)
A6: A. Unsecured Loans (Liability) – Note 2
A7: S. No. | B7: Name of Lender | C7: Amount
A8: 1 | B8: V R Traders – Loan | C8: 405500
A9: 2 | B9: V R Traders – Loan & Advance A/c | C9: 600000
A10: 3 | B10: Ratan Agarwal | C10: 250000
A11: 4 | B11: Bajaj Finance | C11: 37267
B12: TOTAL | C12: =SUM(C8:C11) -> 1292767
A15: B. Other Loans & Advances (Asset) – Note 11
A16: S. No. | B16: Name of Party | C16: Amount
A17: 1 | B17: RENT IN ADVANCE | C17: 57000
A18: 2 | B18: SAMBHU ADV. | C18: 4535
A19: 3 | B19: VINOD ADV. SGT | C19: 15770
A20: 4 | B20: ANKIT ADV. SGT TUGHLAKABAD | C20: 4000
A21: 5 | B21: ASHISH SGT ADV. | C21: 19848
A22: 6 | B22: BRIJMOHAN ADV. | C22: 4530
A23: 7 | B23: CHANDRA KESH ADV. | C23: 6002
A24: 8 | B24: DHANANJAY ADV. | C24: 9550
A25: 9 | B25: HARDEEP ADV. | C25: 7385
A26: 10 | B26: JITENDER ADV. SGT | C26: 19000
A27: 11 | B27: KAMLESH SGT ADV. | C27: 6000
A28: 12 | B28: LOAN FOR JAY GUPTA HITKARI | C28: 2000
... A53: 37 | B53: LOAN TO RAJESH RAJMANDIR | C53: 219970
B54: TOTAL | C54: =SUM(C17:C53) -> 1327580
B57: As per our report of even date attached | C57: For and on behalf of
B58: For G R B & Co. | C58: M/S SHREE GANESHAY TRADERS
B59: Chartered Accountants
B60: FRN: 040755N
C64: ____________________
C65: Vivek Gupta
B66: CA Roopali Garg | C66: Partner
B67: Partner
B68: M. No. 570376 | C68: ____________________
B69: UDIN: ____________________ | C69: Durga Gupta
B70: Place: New Delhi | C70: Partner
B71: Date: ____________

Sheet Sch E - Income Tax
A1: M/S SHREE GANESHAY TRADERS
A2: (A Partnership Firm)
A3: 11/72 Dakshinpuri, New Delhi – 110062 | PAN: ACJFS4485L | MSME: UDYAM-DL-08-0038171
A4: Schedule E – Provision for Income Tax, Advance Tax & TDS (FY 2025-26)
E5: (Amount in ₹)
A6: A. Computation of Tax Payable
B7: Particulars | E7: Amount
B8: Provision for Income Tax for FY 2025-26 | E8: 338416
B9: Less: Advance Tax paid | E9: 225000
B10: Less: TDS Receivable (26AS) | E10: 39561
B11: Net Income Tax Payable (Note 6) | E11: =E8-E9-E10 -> 73855
A14: B. Advance Tax Paid
A15: S. No. | B15: Particulars | E15: Amount
A16: 1 | B16: Advance Tax – Instalment 1 | E16: 60000
A17: 2 | B17: Advance Tax – Instalment 2 | E17: 75000
A18: 3 | B18: Advance Tax – Instalment 3 | E18: 90000
B19: TOTAL | E19: =SUM(E16:E18) -> 225000
A22: C. TDS Deducted by Customers (as per Form 26AS)
A23: S. No. | B23: Name of Deductor | C23: TAN | D23: Amount Paid / Credited | E23: TDS
A24: 1 | B24: PRO NATURE ORGANIC FOODS PRIVATE LIMITED | C24: BLRP08614E | D24: 171000 | E24: 3420
A25: 2 | B25: PRADEEP MITTAL & SONS (HUF) | C25: DELP34264G | D25: 6626 | E25: 7
A26: 3 | B26: PRADEEP MITTAL (HUF) | C26: DELP34934E | D26: 2999976 | E26: 3000
A27: 4 | B27: PRAVEEN KUMAR JAIN | C27: DELP35113B | D27: 716000 | E27: 14320
A28: 5 | B28: RAJMANDIR HYPERMARKET | C28: DELR34630B | D28: 3048232 | E28: 3048
A29: 6 | B29: SANJAY ARORA | C29: DELS36393A | D29: 156918 | E29: 3138
A30: 7 | B30: SLEEPY OWL COFFEE PRIVATE LIMITED | C30: DELS66394G | D30: 103322 | E30: 2068
A31: 8 | B31: VRB CONSUMER PRODUCTS PRIVATE LIMITED | C31: DELV11920G | D31: 528000 | E31: 10560
B32: TOTAL | D32: =SUM(D24:D31) -> 7730074 | E32: =SUM(E24:E31) -> 39561
B35: As per our report of even date attached | D35: For and on behalf of
B36: For G R B & Co. | D36: M/S SHREE GANESHAY TRADERS
B37: Chartered Accountants
B38: FRN: 040755N
D42: ____________________
D43: Vivek Gupta
B44: CA Roopali Garg | D44: Partner
B45: Partner
B46: M. No. 570376 | D46: ____________________
B47: UDIN: ____________________ | D47: Durga Gupta
B48: Place: New Delhi | D48: Partner
B49: Date: ____________

Sheet Sch F - GST Sales Reco
A1: M/S SHREE GANESHAY TRADERS
A2: (A Partnership Firm)
A3: 11/72 Dakshinpuri, New Delhi – 110062 | PAN: ACJFS4485L | MSME: UDYAM-DL-08-0038171
A4: Schedule F – Month-wise Turnover as per GST Returns vs Books (FY 2025-26)
G5: (Amount in ₹)
A6: Month | B6: Taxable Turnover | C6: Exempt / Nil Turnover | D6: Adjustment (Aug-25)* | E6: Total Turnover as per GST | F6: Turnover as per Books | G6: Difference
A7: 45748 | B7: 10082496 | C7: 438964 | D7: 0 | E7: =B7+C7-D7 -> 10521460 | F7: 10520500 | G7: =E7-F7 -> 959.98
A8: 45778 | B8: 12576887 | C8: 494721 | D8: 0 | E8: =B8+C8-D8 -> 13071608 | F8: 13069870 | G8: =E8-F8 -> 1738.28
A9: 45809 | B9: 8765654 | C9: 355659 | D9: 0 | E9: =B9+C9-D9 -> 9121313 | F9: 9113250.7 | G9: =E9-F9 -> 8062.3
A10: 45839 | B10: 10706813 | C10: 402957 | D10: 0 | E10: =B10+C10-D10 -> 11109770 | F10: 10972421 | G10: =E10-F10 -> 137348.53
A11: 45870 | B11: 13003217 | C11: 465835 | D11: 1311432 | E11: =B11+C11-D11 -> 12157620 | F11: 12070686 | G11: =E11-F11 -> 86934.04
A12: 45901 | B12: 11433327 | C12: 752440 | D12: 0 | E12: =B12+C12-D12 -> 12185767 | F12: 12414873 | G12: =E12-F12 -> -229105.64
A13: 45931 | B13: 10234224 | C13: 2069515 | D13: 0 | E13: =B13+C13-D13 -> 12303739 | F13: 12359540 | G13: =E13-F13 -> -55800.91
A14: 45962 | B14: 9027702 | C14: 350914 | D14: 0 | E14: =B14+C14-D14 -> 9378616 | F14: 9442088.7 | G14: =E14-F14 -> -63472.69
A15: 45992 | B15: 8285732 | C15: 503475 | D15: 0 | E15: =B15+C15-D15 -> 8789207 | F15: 8785431 | G15: =E15-F15 -> 3775.97
A16: 46023 | B16: 7541813 | C16: 317546 | D16: 0 | E16: =B16+C16-D16 -> 7859359 | F16: 7857907.5 | G16: =E16-F16 -> 1451.47
A17: 46054 | B17: 7595718 | C17: 469297 | D17: 0 | E17: =B17+C17-D17 -> 8065015 | F17: 8059916.7 | G17: =E17-F17 -> 5098.34
A18: 46082 | B18: 7663249 | C18: 467241 | D18: 0 | E18: =B18+C18-D18 -> 8130490 | F18: 8130490.4 | G18: =E18-F18 -> -0.41
A19: TOTAL | B19: =SUM(B7:B18) -> 116916832 | C19: =SUM(C7:C18) -> 7088564 | D19: =SUM(D7:D18) -> 1311432 | E19: =SUM(E7:E18) -> 1.2269396e+08 | F19: =SUM(F7:F18) -> 1.2279697e+08 | G19: =SUM(G7:G18) -> -103010.74
A21: Turnover as per Books (before adjustment) | E21: =F19 -> 1.2279697e+08
A22: Less: Adjustment entry passed (Sales A/c Dr. to Debtors) | E22: 103010.74
A23: Turnover as per Books after adjustment | E23: =E21-E22 -> 1.2269396e+08
A24: Turnover as per GST Returns | E24: =E19 -> 1.2269396e+08
A25: Revenue as per Statement of Profit & Loss (Note 13) | E25: =Notes!B116 -> 1.2269396e+08
A27: * Invoices of FY 2024-25 amounting to ₹13,11,431.96 (taxable) were reported in GSTR-1 of August 2025; the same are excluded from FY 2025-26 turnover above.
A28: The small residual difference is on account of rounding off in invoices.
A31: As per our report of even date attached | E31: For and on behalf of
A32: For G R B & Co. | E32: M/S SHREE GANESHAY TRADERS
A33: Chartered Accountants
A34: FRN: 040755N
E38: ____________________
E39: Vivek Gupta
A40: CA Roopali Garg | E40: Partner
A41: Partner
A42: M. No. 570376 | E42: ____________________
A43: UDIN: ____________________ | E43: Durga Gupta
A44: Place: New Delhi | E44: Partner
A45: Date: ____________

Sheet Sch G - ESI
A1: M/S SHREE GANESHAY TRADERS
A2: (A Partnership Firm)
A3: 11/72 Dakshinpuri, New Delhi – 110062 | PAN: ACJFS4485L | MSME: UDYAM-DL-08-0038171
A4: Schedule G – ESI Contribution (FY 2025-26)
E5: (Amount in ₹)
A6: Month | B6: Employer's Contribution | C6: Employee's Contribution | D6: Total | E6: Date of Payment
A7: 45748 | B7: 3457 | C7: 801 | D7: =B7+C7 -> 4258 | E7: 45823
A8: 45778 | B8: 3121 | C8: 724 | D8: =B8+C8 -> 3845 | E8: 45823
A9: 45809 | B9: 3530 | C9: 664 | D9: =B9+C9 -> 4194 | E9: 45853
A10: 45839 | B10: 2950 | C10: 683 | D10: =B10+C10 -> 3633 | E10: 45888
A11: 45870 | B11: 3471 | C11: 804 | D11: =B11+C11 -> 4275 | E11: 45915
A12: 45901 | B12: 3430 | C12: 794 | D12: =B12+C12 -> 4224 | E12: 45945
A13: 45931 | B13: 3339 | C13: 773 | D13: =B13+C13 -> 4112 | E13: 45976
A14: 45962 | B14: 3174 | C14: 735 | D14: =B14+C14 -> 3909 | E14: 46006
A15: 45992 | B15: 2911 | C15: 674 | D15: =B15+C15 -> 3585 | E15: 46037
A16: 46023 | B16: 3286 | C16: 760 | D16: =B16+C16 -> 4046 | E16: 46067
A17: 46054 | B17: 3335 | C17: 772 | D17: =B17+C17 -> 4107 | E17: 46096
A18: 46082 | B18: 3188 | C18: 737 | D18: =B18+C18 -> 3925 | E18: 46127
A19: TOTAL | B19: =SUM(B7:B18) -> 39192 | C19: =SUM(C7:C18) -> 8921 | D19: =SUM(D7:D18) -> 48113
A21: Employer's contribution debited to Profit & Loss (Note 18). March 2026 contribution of ₹3,925 paid on 15-04-2026 is shown as ESIC Payable (Note 5).
A25: As per our report of even date attached | D25: For and on behalf of
A26: For G R B & Co. | D26: M/S SHREE GANESHAY TRADERS
A27: Chartered Accountants
A28: FRN: 040755N
D32: ____________________
D33: Vivek Gupta
A34: CA Roopali Garg | D34: Partner
A35: Partner
A36: M. No. 570376 | D36: ____________________
A37: UDIN: ____________________ | D37: Durga Gupta
A38: Place: New Delhi | D38: Partner
A39: Date: ____________

Sheet Sch H - Partner Remuneration
A1: M/S SHREE GANESHAY TRADERS
A2: (A Partnership Firm)
A3: 11/72 Dakshinpuri, New Delhi – 110062 | PAN: ACJFS4485L | MSME: UDYAM-DL-08-0038171
A4: Schedule H – Remuneration to Partners u/s 40(b)(v) of the Income-tax Act, 1961
C5: (Amount in ₹)
A6: Particulars | B6: FY 2025-26 | C6: FY 2024-25
A7: Net Profit before Tax as per Profit & Loss | B7: ='Profit & Loss'!C22 -> 1084667.2 | C7: ='Profit & Loss'!D22 -> 958579.84
A8: Add: Remuneration to Partners debited | B8: =Notes!B156 -> 1200000 | C8: =Notes!C156 -> 1200000
A9: Book Profit | B9: =B7+B8 -> 2284667.2 | C9: =C7+C8 -> 2158579.8
A10: On first ₹6,00,000 of book profit @ 90% (or ₹3,00,000, whichever is higher) | B10: =MAX(300000,MIN(B9,600000)*0.9) -> 540000 | C10: =MAX(300000,MIN(C9,600000)*0.9) -> 540000
A11: On balance book profit @ 60% | B11: =MAX(0,B9-600000)*0.6 -> 1010800.3 | C11: =MAX(0,C9-600000)*0.6 -> 935147.9
A12: Maximum Allowable Remuneration | B12: =B10+B11 -> 1550800.3 | C12: =C10+C11 -> 1475147.9
A13: Remuneration actually paid | B13: =Notes!B156 -> 1200000 | C13: =Notes!C156 -> 1200000
A14: Remuneration disallowable (if any) | B14: =MAX(0,B13-B12) -> 0 | C14: =MAX(0,C13-C12) -> 0
A16: Remuneration paid is within the limit prescribed u/s 40(b)(v); no disallowance is called for. TDS u/s 194T of ₹50,000 on partners' salary is shown under Other Current Liabilities (Note 5).
A20: As per our report of even date attached | B20: For and on behalf of
A21: For G R B & Co. | B21: M/S SHREE GANESHAY TRADERS
A22: Chartered Accountants
A23: FRN: 040755N
B27: ____________________
B28: Vivek Gupta
A29: CA Roopali Garg | B29: Partner
A30: Partner
A31: M. No. 570376 | B31: ____________________
A32: UDIN: ____________________ | B32: Durga Gupta
A33: Place: New Delhi | B33: Partner
A34: Date: ____________
