Workbook

Sheet Balance Sheet
A1: SHREE BALAJEE ENTERPRISE
A2: (Proprietor: Abhishek Gupta) | 11/72 Dakshinpuri, New Delhi-110062 | PAN: BPNPG8069Q
A3: Balance Sheet as at 31st March 2026
A4: (Amount in ₹)
A6: Particulars | B6: Note No. | C6: As at 31.03.2026 | D6: As at 31.03.2025
A7: I. EQUITY AND LIABILITIES
A8: (1) Owners' Funds
A9: (a) Proprietor's Capital Account | B9: 2 | C9: =Notes!$D$21 -> 3542785.5 | D9: =Notes!$E$21 -> 2197208.7
A10: (b) Reserves & Surplus | C10: 0 | D10: 0
C11: =C9+C10 -> 3542785.5 | D11: =D9+D10 -> 2197208.7
A12: (2) Non-Current Liabilities
A13: (a) Long-term Borrowings | B13: 3 | C13: =Notes!$D$28 -> 431245 | D13: =Notes!$E$28 -> 331245
A14: (b) Long-term Provisions | C14: 0 | D14: 0
C15: =C13+C14 -> 431245 | D15: =D13+D14 -> 331245
A16: (3) Current Liabilities
A17: (a) Short-term Borrowings | B17: 4 | C17: =Notes!$D$34 -> 1943724.3 | D17: =Notes!$E$34 -> 1718405.5
A18: (b) Trade Payables | B18: 5 | C18: =Notes!$D$39 -> 1964741.4 | D18: =Notes!$E$39 -> 1453644.3
A19: – Total outstanding dues of Micro & Small Enterprises | C19: =Notes!D40 -> 0 | D19: =Notes!E40 -> 0
A20: – Total outstanding dues of others | C20: =Notes!D41 -> 1964741.4 | D20: =Notes!E41 -> 1453644.3
A21: (c) Other Current Liabilities | B21: 6 | C21: =Notes!$D$46 -> 12500 | D21: =Notes!$E$46 -> 10000
A22: (d) Short-term Provisions | C22: 0 | D22: 0
C23: =C17+C18+C21+C22 -> 3920965.7 | D23: =D17+D18+D21+D22 -> 3182049.8
A24: TOTAL | C24: =C11+C15+C23 -> 7894996.2 | D24: =D11+D15+D23 -> 5710503.5
A25: II. ASSETS
A26: (1) Non-Current Assets
A27: (a) Property, Plant & Equipment | B27: 7 | C27: =Notes!$I$52 -> 458512.58 | D27: =Notes!$I$53 -> 407384.54
A28: (b) Long-term Loans & Advances | B28: 8 | C28: =Notes!$D$59 -> 20000 | D28: =Notes!$E$59 -> 20000
C29: =C27+C28 -> 478512.58 | D29: =D27+D28 -> 427384.54
A30: (2) Current Assets
A31: (a) Inventories | B31: 9 | C31: =Notes!$D$64 -> 2566170 | D31: =Notes!$E$64 -> 2529951.9
A32: (b) Trade Receivables | B32: 10 | C32: =Notes!$D$70 -> 4347307.9 | D32: =Notes!$E$70 -> 2488282.6
A33: (c) Cash & Cash Equivalents | B33: 11 | C33: =Notes!$D$76 -> 324476.46 | D33: =Notes!$E$76 -> 104332.46
A34: (d) Short-term Loans & Advances | B34: 12 | C34: =Notes!$D$84 -> 168173 | D34: =Notes!$E$84 -> 150195.7
A35: (e) Other Current Assets | B35: 13 | C35: =Notes!$D$89 -> 10356.24 | D35: =Notes!$E$89 -> 10356.24
C36: =C31+C32+C33+C34+C35 -> 7416483.6 | D36: =D31+D32+D33+D34+D35 -> 5283119
A37: TOTAL | C37: =C29+C36 -> 7894996.2 | D37: =D29+D36 -> 5710503.5
A39: Check (Liabilities – Assets) → should be zero | C39: =ROUND(C24-C37,2) -> 0 | D39: =ROUND(D24-D37,2) -> 0
A40: Significant Accounting Policies & Notes forming part of the financial statements: Note 1 to 22
A41: As per our report of even date attached
A43: For G R B & CO. | C43: For and on behalf of
...

Sheet Profit & Loss
A1: SHREE BALAJEE ENTERPRISE
A2: (Proprietor: Abhishek Gupta) | 11/72 Dakshinpuri, New Delhi-110062 | PAN: BPNPG8069Q
A3: Statement of Profit & Loss for the year ended 31st March 2026
A4: (Amount in ₹)
A6: Particulars | B6: Note No. | C6: Year ended 31.03.2026 | D6: Year ended 31.03.2025
A7: I. Revenue from Operations | B7: 14 | C7: =Notes!$D$96 -> 23760969 | D7: =Notes!$E$96 -> 21682128
A8: II. Other Income | B8: 15 | C8: =Notes!$D$103 -> 31460.83 | D8: =Notes!$E$103 -> 2836.81
A9: III. Total Income (I + II) | C9: =C7+C8 -> 23792430 | D9: =D7+D8 -> 21684965
A11: IV. Expenses
A12: (a) Purchases of Stock-in-Trade | B12: 16 | C12: =Notes!$D$111 -> 21547909 | D12: =Notes!$E$111 -> 20893747
A13: (b) Changes in Inventories of Stock-in-Trade | B13: 17 | C13: =Notes!$D$117 -> -36218.06 | D13: =Notes!$E$117 -> -1154364.9
A14: (c) Employee Benefits Expense | B14: 18 | C14: =Notes!$D$123 -> 920809.17 | D14: =Notes!$E$123 -> 867399.28
A15: (d) Finance Costs | B15: 19 | C15: =Notes!$D$128 -> 165638 | D15: =Notes!$E$128 -> 75458.2
A16: (e) Depreciation & Amortisation Expense | B16: 20 | C16: =Notes!$H$52 -> 94011 | D16: =Notes!$H$53 -> 81518
A17: (f) Other Expenses | B17: 21 | C17: =Notes!$D$141 -> 477211.53 | D17: =Notes!$E$141 -> 475010.45
A18: Total Expenses (IV) | C18: =SUM(C12:C17) -> 23169360 | D18: =SUM(D12:D17) -> 21238768
A20: V. Profit before Exceptional & Extraordinary Items and Tax (III – IV) | C20: =C9-C18 -> 623069.15 | D20: =D9-D18 -> 446197.26
A21: VI. Exceptional & Extraordinary Items | C21: 0 | D21: 0
A22: VII. Profit before Tax (V – VI) | C22: =C20-C21 -> 623069.15 | D22: =D20-D21 -> 446197.26
A23: VIII. Tax Expense (refer Note 22(d)) | C23: 0 | D23: 0
A24: IX. Profit for the year transferred to Capital Account (VII – VIII) | C24: =C22-C23 -> 623069.15 | D24: =D22-D23 -> 446197.26
A26: Significant Accounting Policies & Notes forming part of the financial statements: Note 1 to 22
A27: As per our report of even date attached
A29: For G R B & CO. | C29: For and on behalf of
A30: Chartered Accountants | C30: SHREE BALAJEE ENTERPRISE
A31: FRN: 040755N
A38: CA Roopali Garg | C38: Abhishek Gupta
A39: Partner | C39: (Proprietor)
A40: M. No.:
A41: Place: New Delhi
A42: Date:
A43: UDIN:
A45: Legend: Blue = values from books · Green = linked from Notes · Yellow = to be filled / verified (MSME, capital difference).

Sheet Notes
A1: SHREE BALAJEE ENTERPRISE
A2: (Proprietor: Abhishek Gupta) | 11/72 Dakshinpuri, New Delhi-110062 | PAN: BPNPG8069Q
A3: Notes forming part of the Financial Statements for the year ended 31st March 2026
A4: (Amount in ₹)
A6: Note 1: Entity Information & Significant Accounting Policies
A7: (a) Entity: Shree Balajee Enterprise is a proprietary concern of Mr. Abhishek Gupta, engaged in wholesale trading/distribution of FMCG, grocery and healthcare products in Delhi.
A8: (b) Basis of preparation: Financial statements are prepared under the historical cost convention on accrual basis, in accordance with the Accounting Standards issued by ICAI (as applicable to non-corporate entities) and presented in the format prescribed by the ICAI Guidance Note on Financial Statements of Non-Corporate Entities.
A9: (c) Inventories: Stock-in-trade is valued at lower of cost and net realisable value, as taken, valued and certified by the proprietor.
A10: (d) Property, Plant & Equipment: Stated at cost less depreciation. Depreciation is provided on WDV method at rates prescribed under the Income-tax Rules; half rate on assets put to use for less than 180 days.
A11: (e) Revenue recognition: Sales are recognised on transfer of significant risks and rewards and are stated net of GST, returns and trade discounts.
A12: (f) GST: Input tax credit is accounted for on accrual basis and adjusted against output liability; unutilised credit is carried as an asset.
A13: (g) Previous year figures have been regrouped/reclassified wherever necessary to conform to current year classification.
A15: Note 2: Proprietor's Capital Account – Abhishek Gupta
A16: Particulars | D16: As at 31.03.2026 | E16: As at 31.03.2025
A17: Opening Balance | D17: 2197208.7 | E17: 1751011.4
A18: Add: Other adjustments – difference vs. books (to be reconciled) | D18: 722507.7 | E18: 0
A19: Add: Net Profit for the year (as per Statement of P&L) | D19: ='Profit & Loss'!C24 -> 623069.15 | E19: ='Profit & Loss'!D24 -> 446197.26
A20: Less: Drawings during the year | D20: 0 | E20: 0
A21: Closing Balance | D21: =D17+D18+D19-D20 -> 3542785.5 | E21: =E17+E18+E19-E20 -> 2197208.7
A23: Note 3: Long-term Borrowings
A24: Particulars | D24: As at 31.03.2026 | E24: As at 31.03.2025
A25: Unsecured
A26: Loan from Shree Ganeshay Trade | D26: 331245 | E26: 331245
A27: Loan from Proprietor – Abhishek Gupta | D27: 100000 | E27: 0
A28: Total | D28: =SUM(D25:D27) -> 431245 | E28: =SUM(E25:E27) -> 331245
A30: Note 4: Short-term Borrowings
A31: Particulars | D31: As at 31.03.2026 | E31: As at 31.03.2025
A32: Secured – Loans repayable on demand from bank
A33: Central Bank of India – Overdraft (secured against stock & book debts) | D33: 1943724.3 | E33: 1718405.5
A34: Total | D34: =SUM(D32:D33) -> 1943724.3 | E34: =SUM(E32:E33) -> 1718405.5
A36: Note 5: Trade Payables
A37: Particulars | D37: As at 31.03.2026 | E37: As at 31.03.2025
A38: Sundry Creditors (for goods & services) | D38: 1964741.4 | E38: 1453644.3
A39: Total | D39: =SUM(D38:D38) -> 1964741.4 | E39: =SUM(E38:E38) -> 1453644.3
A40: Of the above, dues to Micro & Small Enterprises (MSMED Act) – for Sec. 43B(h) / Clause 22
A41: Dues to others | D41: =D39-D40 -> 1964741.4 | E41: =E39-E40 -> 1453644.3
A43: Note 6: Other Current Liabilities
A44: Particulars | D44: As at 31.03.2026 | E44: As at 31.03.2025
A45: Audit Fees Payable | D45: 12500 | E45: 10000
A46: Total | D46: =SUM(D45:D45) -> 12500 | E46: =SUM(E45:E45) -> 10000
...
